Workbook
Name calendário: #N/A
Name calendário: #N/A
Name calendário: #N/A
Name calendário: #N/A
Name calendário: #N/A
Name calendário: #N/A
Name calendário: #N/A
Name calendário: #N/A
Name calendário: #N/A
Name calendário: #N/A
Name calendário: #N/A
Name calendário: #N/A
Name calendário: tabeladedias+[1]Calendário!primeiradata-WEEKDAY([1]Calendário!primeiradata)-diasdasemana_opção
Name DataParaIniciar: '1'!$E$1
Name DataParaIniciar: '10'!$E$1
Name DataParaIniciar: '11'!$E$1
Name DataParaIniciar: '12'!$E$1
Name DataParaIniciar: '2'!$E$1
Name DataParaIniciar: '3'!$E$1
Name DataParaIniciar: '4'!$E$1
Name DataParaIniciar: '5'!$E$1
Name DataParaIniciar: '6'!$E$1
Name DataParaIniciar: '7'!$E$1
Name DataParaIniciar: '8'!$E$1
Name DataParaIniciar: '9'!$E$1
Name DataParaIniciar: #REF!
Name dias: {0,1,2,3,4,5,6}
Name diasdasemana_opção: MATCH('1'!DataParaIniciar,[0]!diasdasemana_posteriores,0)-2
Name diasdasemana_opção: MATCH('10'!DataParaIniciar,[0]!diasdasemana_posteriores,0)-2
Name diasdasemana_opção: MATCH('11'!DataParaIniciar,[0]!diasdasemana_posteriores,0)-2
Name diasdasemana_opção: MATCH('12'!DataParaIniciar,[0]!diasdasemana_posteriores,0)-2
Name diasdasemana_opção: MATCH('2'!DataParaIniciar,[0]!diasdasemana_posteriores,0)-2
Name diasdasemana_opção: MATCH('3'!DataParaIniciar,[0]!diasdasemana_posteriores,0)-2
Name diasdasemana_opção: MATCH('4'!DataParaIniciar,[0]!diasdasemana_posteriores,0)-2
Name diasdasemana_opção: MATCH('5'!DataParaIniciar,[0]!diasdasemana_posteriores,0)-2
Name diasdasemana_opção: MATCH('6'!DataParaIniciar,[0]!diasdasemana_posteriores,0)-2
Name diasdasemana_opção: MATCH('7'!DataParaIniciar,[0]!diasdasemana_posteriores,0)-2
Name diasdasemana_opção: MATCH('8'!DataParaIniciar,[0]!diasdasemana_posteriores,0)-2
Name diasdasemana_opção: MATCH('9'!DataParaIniciar,[0]!diasdasemana_posteriores,0)-2
Name diasdasemana_opção: MATCH(DataParaIniciar,diasdasemana_posteriores,0)-2
Name diasdasemana_posteriores: {"Domingo","Sábado","Sexta-feira","Quinta-feira","Quarta-feira","Terça-feira","Segunda-feira"}
Name meses: {"Janeiro","Fevereiro","Março","Abril","Maio","Junho","Julho","Agosto","Setembro","Outubro","Novembro","Dezembro"}
Name MêsParaExibiçãoNúmero: MATCH([1]Calendário!MêsParaExibição,meses,0)
Name MêsParaExibiçãoNúmero: MATCH([1]Calendário!MêsParaExibição,meses,0)
Name MêsParaExibiçãoNúmero: MATCH([1]Calendário!MêsParaExibição,meses,0)
Name MêsParaExibiçãoNúmero: MATCH([1]Calendário!MêsParaExibição,meses,0)
Name MêsParaExibiçãoNúmero: MATCH([1]Calendário!MêsParaExibição,meses,0)
Name MêsParaExibiçãoNúmero: MATCH([1]Calendário!MêsParaExibição,meses,0)
Name MêsParaExibiçãoNúmero: MATCH([1]Calendário!MêsParaExibição,meses,0)
Name MêsParaExibiçãoNúmero: MATCH([1]Calendário!MêsParaExibição,meses,0)
Name MêsParaExibiçãoNúmero: MATCH([1]Calendário!MêsParaExibição,meses,0)
Name MêsParaExibiçãoNúmero: MATCH([1]Calendário!MêsParaExibição,meses,0)
Name MêsParaExibiçãoNúmero: MATCH([1]Calendário!MêsParaExibição,meses,0)
Name MêsParaExibiçãoNúmero: MATCH([1]Calendário!MêsParaExibição,meses,0)
Name MêsParaExibiçãoNúmero: MATCH([1]Calendário!MêsParaExibição,meses,0)
Name ndx: ROUNDUP(MATCH(2,1/FREQUENCY(DATE([1]Calendário!AnoParaExibição,[1]Calendário!MêsParaExibiçãoNúmero,1),[1]Calendário!calendário))/7,0)
Name ndx: ROUNDUP(MATCH(2,1/FREQUENCY(DATE([1]Calendário!AnoParaExibição,[1]Calendário!MêsParaExibiçãoNúmero,1),[1]Calendário!calendário))/7,0)
Name ndx: ROUNDUP(MATCH(2,1/FREQUENCY(DATE([1]Calendário!AnoParaExibição,[1]Calendário!MêsParaExibiçãoNúmero,1),[1]Calendário!calendário))/7,0)
Name ndx: ROUNDUP(MATCH(2,1/FREQUENCY(DATE([1]Calendário!AnoParaExibição,[1]Calendário!MêsParaExibiçãoNúmero,1),[1]Calendário!calendário))/7,0)
Name ndx: ROUNDUP(MATCH(2,1/FREQUENCY(DATE([1]Calendário!AnoParaExibição,[1]Calendário!MêsParaExibiçãoNúmero,1),[1]Calendário!calendário))/7,0)

Sheet 2021 RESUL. FX ETÁRIA
A1: 2021 - Resultados Alcançados MENSAL (POR FAIXA ETÁRIA)
A4: INDICADORES DE DESEMPENHO | P4: TOTAL | Q4: TOTAL
D5: JAN | E5: FEV | F5: MAR | G5: ABR | H5: MAI | I5: JUN | J5: JUL | K5: AGO | L5: SET | M5: OUT | N5: NOV | O5: DEZ
A6: Restaurante Popular CENTRO | B6: Usuários por faixa etária | C6: 0-16 anos M | D6: 199 | E6: 296 | F6: 348 | G6: 304 | H6: 348 | I6: 150 | J6: 217 | K6: 259 | L6: 264 | M6: =AVERAGE(I6:L6) -> 222.5 | N6: =AVERAGE(I6:L6) -> 222.5 | O6: =AVERAGE(I6:L6) -> 222.5 | P6: =SUM(D6:O6) -> 3052.5 | Q6: =P6+P7 -> 5228
C7: 0-16 anos F | D7: 180 | E7: 255 | F7: 255 | G7: 170 | H7: 255 | I7: 120 | J7: 167 | K7: 154 | L7: 165 | M7: =AVERAGE(I7:L7) -> 151.5 | N7: =AVERAGE(I7:L7) -> 151.5 | O7: =AVERAGE(I7:L7) -> 151.5 | P7: =SUM(D7:O7) -> 2175.5
C8: 17-60 anos M | D8: 2419 | E8: 3141 | F8: 4491 | G8: 3822 | H8: 4491 | I8: 3726 | J8: 4706 | K8: 4908 | L8: 4684 | M8: =AVERAGE(I8:L8) -> 4506 | N8: =AVERAGE(I8:L8) -> 4506 | O8: =AVERAGE(I8:L8) -> 4506 | P8: =SUM(D8:O8) -> 49906 | Q8: =P8+P9 -> 63949.25
C9: 17-60 anos F | D9: 762 | E9: 1207 | F9: 1338 | G9: 1161 | H9: 1338 | I9: 950 | J9: 1250 | K9: 1288 | L9: 1219 | M9: =AVERAGE(I9:L9) -> 1176.75 | N9: =AVERAGE(I9:L9) -> 1176.75 | O9: =AVERAGE(I9:L9) -> 1176.75 | P9: =SUM(D9:O9) -> 14043.25
C10: mais 60 anos M | D10: 1023 | E10: 1360 | F10: 2033 | G10: 1910 | H10: 2033 | I10: 2346 | J10: 3104 | K10: 3430 | L10: 3400 | M10: =AVERAGE(I10:L10) -> 3070 | N10: =AVERAGE(I10:L10) -> 3070 | O10: =AVERAGE(I10:L10) -> 3070 | P10: =SUM(D10:O10) -> 29849 | Q10: =P10+P11 -> 34237.75
C11: mais 60 anos F | D11: 155 | E11: 245 | F11: 442 | G11: 513 | H11: 442 | I11: 240 | J11: 381 | K11: 439 | L11: 421 | M11: =AVERAGE(I11:L11) -> 370.25 | N11: =AVERAGE(I11:L11) -> 370.25 | O11: =AVERAGE(I11:L11) -> 370.25 | P11: =SUM(D11:O11) -> 4388.75
A12: Restaurante Popular COMPENSA | B12: Usuários por faixa etária | C12: 0-16 anos M | D12: 203 | E12: 166 | F12: 190 | G12: 189 | H12: 190 | I12: 269 | J12: 207 | K12: 239 | L12: 232 | M12: =AVERAGE(I12:L12) -> 236.75 | N12: =AVERAGE(I12:L12) -> 236.75 | O12: =AVERAGE(I12:L12) -> 236.75 | P12: =SUM(D12:O12) -> 2595.25 | Q12: =P12+P13 -> 5652.25
C13: 0-16 anos F | D13: 177 | E13: 193 | F13: 147 | G13: 90 | H13: 147 | I13: 321 | J13: 324 | K13: 366 | L13: 305 | M13: =AVERAGE(I13:L13) -> 329 | N13: =AVERAGE(I13:L13) -> 329 | O13: =AVERAGE(I13:L13) -> 329 | P13: =SUM(D13:O13) -> 3057
C14: 17-60 anos M | D14: 1700 | E14: 1446 | F14: 1828 | G14: 1582 | H14: 1828 | I14: 2317 | J14: 2242 | K14: 2472 | L14: 2332 | M14: =AVERAGE(I14:L14) -> 2340.75 | N14: =AVERAGE(I14:L14) -> 2340.75 | O14: =AVERAGE(I14:L14) -> 2340.75 | P14: =SUM(D14:O14) -> 24769.25 | Q14: =P14+P15 -> 35167.75
C15: 17-60 anos F | D15: 832 | E15: 698 | F15: 881 | G15: 901 | H15: 881 | I15: 695 | J15: 843 | K15: 1000 | L15: 1008 | M15: =AVERAGE(I15:L15) -> 886.5 | N15: =AVERAGE(I15:L15) -> 886.5 | O15: =AVERAGE(I15:L15) -> 886.5 | P15: =SUM(D15:O15) -> 10398.5
C16: mais 60 anos M | D16: 740 | E16: 634 | F16: 935 | G16: 750 | H16: 935 | I16: 901 | J16: 1045 | K16: 1350 | L16: 1313 | M16: =AVERAGE(I16:L16) -> 1152.25 | N16: =AVERAGE(I16:L16) -> 1152.25 | O16: =AVERAGE(I16:L16) -> 1152.25 | P16: =SUM(D16:O16) -> 12059.75 | Q16: =P16+P17 -> 16146
C17: mais 60 anos F | D17: 302 | E17: 321 | F17: 406 | G17: 301 | H17: 406 | I17: 222 | J17: 339 | K17: 381 | L17: 401 | M17: =AVERAGE(I17:L17) -> 335.75 | N17: =AVERAGE(I17:L17) -> 335.75 | O17: =AVERAGE(I17:L17) -> 335.75 | P17: =SUM(D17:O17) -> 4086.25
A18: Restaurante Popular JORGE TEIXEIRA | B18: Usuários por faixa etária | C18: 0-16 anos M | D18: 37 | E18: - | F18: - | G18: - | H18: - | I18: - | J18: - | K18: - | L18: 921 | M18: =AVERAGE(I18:L18) -> 921 | N18: =AVERAGE(I18:L18) -> 921 | O18: =AVERAGE(I18:L18) -> 921 | P18: =SUM(D18:O18) -> 3721 | Q18: =P18+P19 -> 6752
C19: 0-16 anos F | D19: 35 | E19: - | F19: - | G19: - | H19: - | I19: - | J19: - | K19: - | L19: 749 | M19: =AVERAGE(I19:L19) -> 749 | N19: =AVERAGE(I19:L19) -> 749 | O19: =AVERAGE(I19:L19) -> 749 | P19: =SUM(D19:O19) -> 3031
C20: 17-60 anos M | D20: 162 | E20: - | F20: - | G20: - | H20: - | I20: - | J20: - | K20: - | L20: 3538 | M20: =AVERAGE(I20:L20) -> 3538 | N20: =AVERAGE(I20:L20) -> 3538 | O20: =AVERAGE(I20:L20) -> 3538 | P20: =SUM(D20:O20) -> 14314 | Q20: =P20+P21 -> 23272
C21: 17-60 anos F | D21: 170 | E21: - | F21: - | G21: - | H21: - | I21: - | J21: - | K21: - | L21: 2197 | M21: =AVERAGE(I21:L21) -> 2197 | N21: =AVERAGE(I21:L21) -> 2197 | O21: =AVERAGE(I21:L21) -> 2197 | P21: =SUM(D21:O21) -> 8958
C22: mais 60 anos M | D22: 69 | E22: - | F22: - | G22: - | H22: - | I22: - | J22: - | K22: - | L22: 1292 | M22: =AVERAGE(I22:L22) -> 1292 | N22: =AVERAGE(I22:L22) -> 1292 | O22: =AVERAGE(I22:L22) -> 1292 | P22: =SUM(D22:O22) -> 5237 | Q22: =P22+P23 -> 6735
C23: mais 60 anos F | D23: 18 | E23: - | F23: - | G23: - | H23: - | I23: - | J23: - | K23: - | L23: 370 | M23: =AVERAGE(I23:L23) -> 370 | N23: =AVERAGE(I23:L23) -> 370 | O23: =AVERAGE(I23:L23) -> 370 | P23: =SUM(D23:O23) -> 1498
A24: Restaurante Popular NOVO ISRAEL | B24: Usuários por faixa etária | C24: 0-16 anos M | D24: 31 | E24: - | F24: - | G24: - | H24: - | I24: - | J24: - | K24: - | L24: - | M24: - | N24: - | O24: - | P24: =SUM(D24:O24) -> 31 | Q24: =P24+P25 -> 62
C25: 0-16 anos F | D25: 31 | E25: - | F25: - | G25: - | H25: - | I25: - | J25: - | K25: - | L25: - | M25: - | N25: - | O25: - | P25: =SUM(D25:O25) -> 31
C26: 17-60 anos M | D26: 158 | E26: - | F26: - | G26: - | H26: - | I26: - | J26: - | K26: - | L26: - | M26: - | N26: - | O26: - | P26: =SUM(D26:O26) -> 158 | Q26: =P26+P27 -> 261
C27: 17-60 anos F | D27: 103 | E27: - | F27: - | G27: - | H27: - | I27: - | J27: - | K27: - | L27: - | M27: - | N27: - | O27: - | P27: =SUM(D27:O27) -> 103
C28: mais 60 anos M | D28: 72 | E28: - | F28: - | G28: - | H28: - | I28: - | J28: - | K28: - | L28: - | M28: - | N28: - | O28: - | P28: =SUM(D28:O28) -> 72 | Q28: =P28+P29 -> 93
C29: mais 60 anos F | D29: 21 | E29: - | F29: - | G29: - | H29: - | I29: - | J29: - | K29: - | L29: - | M29: - | N29: - | O29: - | P29: =SUM(D29:O29) -> 21
A30: Cozinha ALFREDO NASCIMENTO | B30: Usuários por faixa etária | C30: 0-16 anos M | D30: 2616 | E30: 2536 | F30: 3123 | G30: 2788 | H30: 3123 | I30: 2241 | J30: 2828 | K30: 1239 | L30: - | M30: =AVERAGE(I30:L30) -> 2102.6667 | N30: =AVERAGE(I30:L30) -> 2102.6667 | O30: =AVERAGE(I30:L30) -> 2102.6667 | P30: =SUM(D30:O30) -> 26802 | Q30: =P30+P31 -> 51923
C31: 0-16 anos F | D31: 2143 | E31: 2204 | F31: 2917 | G31: 2540 | H31: 2917 | I31: 2242 | J31: 2750 | K31: 1208 | L31: - | M31: =AVERAGE(I31:L31) -> 2066.6667 | N31: =AVERAGE(I31:L31) -> 2066.6667 | O31: =AVERAGE(I31:L31) -> 2066.6667 | P31: =SUM(D31:O31) -> 25121
C32: 17-60 anos M | D32: 7493 | E32: 7178 | F32: 8670 | G32: 7639 | H32: 8670 | I32: 7370 | J32: 8868 | K32: 3838 | L32: - | M32: =AVERAGE(I32:L32) -> 6692 | N32: =AVERAGE(I32:L32) -> 6692 | O32: =AVERAGE(I32:L32) -> 6692 | P32: =SUM(D32:O32) -> 79802 | Q32: =P32+P33 -> 153148
C33: 17-60 anos F | D33: 6919 | E33: 6641 | F33: 8322 | G33: 7414 | H33: 8322 | I33: 6407 | J33: 7915 | K33: 3542 | L33: - | M33: =AVERAGE(I33:L33) -> 5954.6667 | N33: =AVERAGE(I33:L33) -> 5954.6667 | O33: =AVERAGE(I33:L33) -> 5954.6667 | P33: =SUM(D33:O33) -> 73346
C34: mais 60 anos M | D34: 989 | E34: 789 | F34: 920 | G34: 848 | H34: 920 | I34: 680 | J34: 938 | K34: 396 | L34: - | M34: =AVERAGE(I34:L34) -> 671.33333 | N34: =AVERAGE(I34:L34) -> 671.33333 | O34: =AVERAGE(I34:L34) -> 671.33333 | P34: =SUM(D34:O34) -> 8494 | Q34: =P34+P35 -> 15847
C35: mais 60 anos F | D35: 772 | E35: 699 | F35: 930 | G35: 726 | H35: 930 | I35: 583 | J35: 706 | K35: 359 | L35: - | M35: =AVERAGE(I35:L35) -> 549.33333 | N35: =AVERAGE(I35:L35) -> 549.33333 | O35: =AVERAGE(I35:L35) -> 549.33333 | P35: =SUM(D35:O35) -> 7353
A36: Cozinha PARQUE SÃO PEDRO | B36: Usuários por faixa etária | C36: 0-16 anos M | D36: 1794 | E36: 193 | F36: - | G36: - | H36: - | I36: - | J36: - | K36: - | L36: - | M36: - | N36: - | O36: - | P36: =SUM(D36:O36) -> 1987 | Q36: =P36+P37 -> 3739
C37: 0-16 anos F | D37: 1576 | E37: 176 | F37: - | G37: - | H37: - | I37: - | J37: - | K37: - | L37: - | M37: - | N37: - | O37: - | P37: =SUM(D37:O37) -> 1752
C38: 17-60 anos M | D38: 7664 | E38: 800 | F38: - | G38: - | H38: - | I38: - | J38: - | K38: - | L38: - | M38: - | N38: - | O38: - | P38: =SUM(D38:O38) -> 8464 | Q38: =P38+P39 -> 15759
C39: 17-60 anos F | D39: 6596 | E39: 699 | F39: - | G39: - | H39: - | I39: - | J39: - | K39: - | L39: - | M39: - | N39: - | O39: - | P39: =SUM(D39:O39) -> 7295
C40: mais 60 anos M | D40: 757 | E40: 77 | F40: - | G40: - | H40: - | I40: - | J40: - | K40: - | L40: - | M40: - | N40: - | O40: - | P40: =SUM(D40:O40) -> 834 | Q40: =P40+P41 -> 1895
C41: mais 60 anos F | D41: 962 | E41: 99 | F41: - | G41: - | H41: - | I41: - | J41: - | K41: - | L41: - | M41: - | N41: - | O41: - | P41: =SUM(D41:O41) -> 1061
A42: Cozinha RIO PIORINI | B42: Usuários por faixa etária | C42: 0-16 anos M | D42: 100 | E42: - | F42: - | G42: 1175 | H42: - | I42: - | J42: - | K42: - | L42: - | M42: - | N42: - | O42: - | P42: =SUM(D42:O42) -> 1275 | Q42: =P42+P43 -> 2542
...

Sheet RESUL. ALCANÇADOS
B1: 2026 | M1: RESTAURANTES RESULTADOS ALCANÇADOS
B3: \ | C3: INDICADORES CENTRO | D3: ANO 2018 | E3: ANO 2019 | F3: ANO 2020 | G3: ANO 2021 | H3: ANO 2022 | I3: ANO 2023 | J3: ANO 2024 | K3: ANO 2025 | L3: ANO 2026 | M3: JAN | N3: FEV | O3: MAR | P3: ABR | Q3: MAI | R3: JUN | S3: JUL | T3: AGO | U3: SET | V3: OUT | W3: NOV | X3: DEZ | Y3: TOTAL 2026
A4: RESTAURANTES POPULARES | B4: CENTRO | C4: Novos Cadastros | D4: 0 | E4: 4632 | F4: 2694 | G4: 3130 | H4: 4119 | I4: 5902 | J4: 2056 | K4: 929 | L4: =SUM(M4:X4) -> 306 | M4: ='1'!$AI$4 -> 66 | N4: ='2'!$AF$4 -> 57 | O4: ='3'!$AI$4 -> 160 | P4: ='4'!$AH$4 -> 23 | Q4: ='5'!AI4 -> 0 | R4: ='6'!$AH$4 -> 0 | S4: ='7'!$AI$4 -> 0 | T4: ='8'!$AI$4 -> 0 | U4: ='9'!$AH$4 -> 0 | V4: ='10'!$AI$4 -> 0 | W4: ='11'!$AH$4 -> 0 | X4: ='12'!$AI$4 -> 0 | Y4: =SUM(M4:P4) -> 306
C5: Pessoas em situação de rua | D5: 0 | E5: 0 | F5: 1915 | G5: 4443 | H5: 6164 | I5: 15699 | J5: 12254 | K5: 10609 | L5: =SUM(M5:X5) -> 8460 | M5: =SUM('1'!$AI$17:$AI$18) -> 2493 | N5: =SUM('2'!$AF$17:$AF$18) -> 1676 | O5: =SUM('3'!$AI$17:$AI$18) -> 2493 | P5: =SUM('4'!$AH$17:$AH$18) -> 85 | Q5: =SUM('5'!$AI$17:$AI$18) -> 869 | R5: =SUM('6'!$AH$17:$AH$18) -> 844 | S5: =SUM('7'!$AI$17:$AI$18) -> 0 | T5: =SUM('8'!$AI$17:$AI$18) -> 0 | U5: =SUM('9'!$AH$17:$AH$18) -> 0 | V5: =SUM('10'!$AI$17:$AI$18) -> 0 | W5: =SUM('11'!$AI$17:$AI$18) -> 0 | X5: =SUM('12'!$AI$17:$AI$18) -> 0 | Y5: =SUM(M5:X5) -> 8460
C6: Genéricas | E6: - | F6: - | G6: - | H6: - | J6: 7047 | K6: 51001 | L6: =SUM(M6:X6) -> 22742 | M6: ='1'!$AI$19 -> 3857 | N6: ='2'!$AF$19 -> 3820 | O6: ='3'!$AI$19 -> 4036 | P6: ='4'!$AH$19 -> 4844 | Q6: ='5'!$AI$19 -> 4233 | R6: ='6'!$AH$19 -> 1952 | S6: ='7'!$AI$19 -> 0 | T6: ='8'!$AI$19 -> 0 | U6: ='9'!$AH$19 -> 0 | V6: ='10'!$AI$19 -> 0 | W6: ='11'!$AH$19 -> 0 | X6: ='12'!$AI$19 -> 0 | Y6: =SUM(M6:X6) -> 22742
C7: Usuários Atendidos (vendidos) | D7: 0 | E7: 23557 | F7: 76735 | G7: 109488 | H7: 122080 | I7: 141610 | J7: 142000 | K7: 143474 | L7: =SUM(M7:X7) -> 65768 | M7: ='1'!$AI$20 -> 12577 | N7: ='2'!$AF$20 -> 10512 | O7: ='3'!$AI$20 -> 13011 | P7: ='4'!$AH$20 -> 11826 | Q7: ='5'!$AI$20 -> 11842 | R7: ='6'!$AH$20 -> 6000 | S7: ='7'!$AI$20 -> 0 | T7: ='8'!$AI$20 -> 0 | U7: ='9'!$AH$20 -> 0 | V7: ='10'!$AI$20 -> 0 | W7: ='11'!$AH$20 -> 0 | X7: ='12'!$AI$20 -> 0 | Y7: =SUM(M7:X7) -> 65768
C8: Refeições Servidas | D8: 0 | E8: 148666 | F8: 78772 | G8: 111770 | H8: 117827 | I8: 135782 | J8: 137578 | K8: 140097 | L8: =SUM(M8:X8) -> 64336 | M8: ='1'!$AI$21 -> 12319 | N8: ='2'!$AF$21 -> 10320 | O8: ='3'!$AI$21 -> 12683 | P8: ='4'!$AH$21 -> 11579 | Q8: ='5'!$AI$21 -> 11566 | R8: ='6'!$AH$21 -> 5869 | S8: ='7'!$AI$21 -> 0 | T8: ='8'!$AI$21 -> 0 | U8: ='9'!$AH$21 -> 0 | V8: ='10'!$AI$21 -> 0 | W8: ='11'!$AH$21 -> 0 | X8: ='12'!$AI$21 -> 0 | Y8: =SUM(M8:X8) -> 64336
C9: Refeições Ofertadas | E9: - | F9: - | G9: - | H9: - | J9: 12600 | K9: 148200 | L9: =SUM(M9:X9) -> 153000 | M9: ='1'!$AI$22 -> 12600 | N9: ='2'!$AF$22 -> 10800 | O9: ='3'!$AI$22 -> 13200 | P9: ='4'!$AH$22 -> 12000 | Q9: ='5'!$AI$22 -> 12000 | R9: ='6'!$AH$22 -> 12600 | S9: ='7'!$AI$22 -> 13800 | T9: ='8'!$AI$22 -> 12600 | U9: ='9'!$AH$22 -> 13200 | V9: ='10'!$AI$22 -> 13200 | W9: ='11'!$AH$25 -> 13200 | X9: ='12'!$AI$22 -> 13800 | Y9: =SUM(M9:X9) -> 153000
C10: Pessoas com Deficiência | E10: 2299 | F10: 2161 | G10: 2602 | H10: 732 | I10: 3817 | J10: 1154 | K10: 1836 | L10: =SUM(M10:X10) -> 1144 | M10: ='1'!$AI$25 -> 138 | N10: ='2'!$AF$25 -> 459 | O10: ='3'!$AI$25 -> 190 | P10: ='4'!$AH$25 -> 357 | Q10: ='5'!$AI$25 -> 0 | R10: ='6'!$AH$25 -> 0 | S10: ='7'!$AI$25 -> 0 | T10: ='8'!$AI$25 -> 0 | U10: ='9'!$AH$25 -> 0 | V10: ='10'!$AI$25 -> 0 | W10: 0 | X10: ='12'!$AI$25 -> 0 | Y10: =SUM(M10:X10) -> 1144
B11: UNIDADE | C11: INDICADORES COMPENSA | D11: ANO 2018 | E11: ANO 2019 | F11: ANO 2020 | G11: ANO 2021 | H11: ANO 2022 | I11: ANO 2023 | J11: ANO 2024 | K11: ANO 2025 | L11: ANO 2026 | M11: JAN | N11: FEV | O11: MAR | P11: ABR | Q11: MAI | R11: JUN | S11: JUL | T11: AGO | U11: SET | V11: OUT | W11: NOV | X11: DEZ | Y11: TOTAL 2026
B12: COMPENSA | C12: Novos Cadastros | D12: 0 | E12: 1674 | F12: 240 | G12: 898 | H12: 851 | I12: 1623 | J12: 470 | K12: 51 | L12: =SUM(M12:X12) -> 104 | M12: ='1'!$AI$27 -> 0 | N12: ='2'!$AF$27 -> 11 | O12: ='3'!$AI$27 -> 74 | P12: ='4'!$AH$27 -> 19 | Q12: ='5'!AI27 -> 0 | R12: ='6'!$AH$27 -> 0 | S12: ='7'!$AI$27 -> 0 | T12: ='8'!$AI$27 -> 0 | U12: ='9'!$AH$27 -> 0 | V12: ='10'!$AI$27 -> 0 | W12: ='11'!$AH$27 -> 0 | X12: ='12'!$AI$27 -> 0 | Y12: =SUM(M12:X12) -> 104
C13: Pessoas em situação de rua | D13: 0 | E13: 0 | F13: 0 | G13: 372 | H13: 1827 | I13: 2473 | J13: 769 | K13: 0 | L13: =SUM(M13:X13) -> 939 | M13: =SUM('1'!$AI$40:$AI$41) -> 0 | N13: =SUM('2'!$AF$40:$AF$41) -> 35 | O13: =SUM('3'!$AI$40:$AI$41) -> 411 | P13: =SUM('4'!$AH$40:$AH$41) -> 186 | Q13: =SUM('5'!$AI$40:$AI$41) -> 171 | R13: =SUM('6'!$AH$40:$AH$41) -> 136 | S13: =SUM('7'!$AI$40:$AI$41) -> 0 | T13: =SUM('8'!$AI$40:$AI$41) -> 0 | U13: =SUM('9'!$AH$40:$AH$41) -> 0 | V13: =SUM('10'!$AI$40:$AI$41) -> 0 | W13: =SUM('11'!$AH$40:$AH$41) -> 0 | X13: =SUM('12'!$AI$40:$AI$41) -> 0 | Y13: =SUM(M13:X13) -> 939
C14: Genéricas | J14: 0 | K14: 0 | L14: =SUM(M14:X14) -> 821 | M14: ='1'!$AI$42 -> 0 | N14: ='2'!$AF$42 -> 35 | O14: ='3'!$AI$42 -> 216 | P14: ='4'!$AH$42 -> 162 | Q14: ='5'!$AI$42 -> 277 | R14: ='6'!$AH$42 -> 131 | S14: ='7'!$AI$42 -> 0 | T14: ='8'!$AI$42 -> 0 | U14: ='9'!$AH$42 -> 0 | V14: ='10'!$AI$42 -> 0 | W14: ='11'!$AH$42 -> 0 | X14: ='12'!$AI$42 -> 0 | Y14: =SUM(M14:X14) -> 821
C15: Usuários Atendidos (vendidos) | D15: 0 | E15: 14773 | F15: 38079 | G15: 57645 | H15: 62695 | I15: 63375 | J15: 66213 | K15: 64994 | L15: =SUM(M15:X15) -> 29306 | M15: ='1'!$AI$43 -> 5612 | N15: ='2'!$AF$43 -> 4582 | O15: ='3'!$AI$43 -> 5910 | P15: ='4'!$AH$43 -> 5229 | Q15: ='5'!$AI$43 -> 5319 | R15: ='6'!$AH$43 -> 2654 | S15: ='7'!$AI$43 -> 0 | T15: ='8'!$AI$43 -> 0 | U15: ='9'!$AH$43 -> 0 | V15: ='10'!$AI$43 -> 0 | W15: ='11'!$AH$43 -> 0 | X15: ='12'!$AI$43 -> 0 | Y15: =SUM(M15:X15) -> 29306
C16: Refeições Servidas | D16: 0 | E16: 73290 | F16: 42954 | G16: =Y16 -> 28827 | H16: 59772 | I16: 60953 | J16: 62977 | K16: 62286 | L16: =SUM(M16:X16) -> 28827 | M16: ='1'!$AI$44 -> 5425 | N16: ='2'!$AF$44 -> 4489 | O16: ='3'!$AI$44 -> 5875 | P16: ='4'!$AH$44 -> 5169 | Q16: ='5'!$AI$44 -> 5258 | R16: ='6'!$AH$44 -> 2611 | S16: ='7'!$AI$44 -> 0 | T16: ='8'!$AI$44 -> 0 | U16: ='9'!$AH$44 -> 0 | V16: ='10'!$AI$44 -> 0 | W16: ='11'!$AH$44 -> 0 | X16: ='12'!$AI$44 -> 0 | Y16: =SUM(M16:X16) -> 28827
C17: Refeições Ofertadas | J17: 5400 | K17: 67020 | L17: =SUM(M17:X17) -> 68310 | M17: ='1'!$AI$45 -> 5670 | N17: ='2'!$AF$45 -> 4860 | O17: ='3'!$AI$45 -> 5940 | P17: ='4'!$AH$45 -> 5400 | Q17: ='5'!$AI$45 -> 5400 | R17: ='6'!$AH$45 -> 5670 | S17: ='7'!$AI$45 -> 6210 | T17: ='8'!$AI$45 -> 5670 | U17: ='9'!$AH$45 -> 5940 | V17: ='10'!$AI$45 -> 5940 | W17: ='11'!$AH$48 -> 5400 | X17: ='12'!$AI$45 -> 6210 | Y17: =SUM(M17:X17) -> 68310
C18: Pessoas com Deficiência | E18: 1122 | F18: 1039 | G18: =Y18 -> 498 | H18: 1791 | I18: 2267 | J18: 1983 | K18: 45 | L18: =SUM(M18:X18) -> 498 | M18: ='1'!$AI$48 -> 0 | N18: ='2'!$AF$48 -> 28 | O18: ='3'!$AI$48 -> 350 | P18: ='4'!$AH$48 -> 120 | Q18: ='5'!$AI$48 -> 0 | R18: ='6'!$AH$48 -> 0 | S18: ='7'!$AI$48 -> 0 | T18: ='8'!$AI$48 -> 0 | U18: ='9'!$AH$48 -> 0 | V18: ='10'!$AI$48 -> 0 | W18: 0 | X18: ='12'!$AI$48 -> 0 | Y18: =SUM(M18:X18) -> 498
B19: UNIDADE | C19: INDICADORES JORGE TEIXEIRA | D19: ANO 2018 | E19: ANO 2019 | F19: ANO 2020 | G19: ANO 2021 | H19: ANO 2022 | I19: ANO 2023 | J19: ANO 2024 | K19: ANO 2025 | L19: ANO 2026 | M19: JAN | N19: FEV | O19: MAR | P19: ABR | Q19: MAI | R19: JUN | S19: JUL | T19: AGO | U19: SET | V19: OUT | W19: NOV | X19: DEZ | Y19: TOTAL 2026
B20: JORGE TEIXEIRA | C20: Novos Cadastros | D20: 0 | E20: 1856 | F20: 1254 | G20: 1935 | H20: 1869 | I20: 214 | J20: 15 | K20: 331 | L20: =SUM(M20:X20) -> 356 | M20: ='1'!$AI$50 -> 77 | N20: ='2'!$AF$50 -> 73 | O20: ='3'!$AI$50 -> 82 | P20: ='4'!$AH$50 -> 99 | Q20: ='5'!AI50 -> 25 | R20: ='6'!$AH$50 -> 0 | S20: ='7'!$AI$50 -> 0 | T20: ='8'!$AI$50 -> 0 | U20: ='9'!$AH$50 -> 0 | V20: ='10'!$AI$50 -> 0 | W20: ='11'!$AH$50 -> 0 | X20: ='12'!$AI$50 -> 0 | Y20: =SUM(M20:X20) -> 356
C21: Pessoas em situação de rua | D21: 0 | E21: 0 | F21: 3114 | G21: 4168 | H21: 12264 | I21: 62 | J21: 16 | K21: 2111 | L21: =SUM(M21:X21) -> 3158 | M21: =SUM('1'!$AI$63:$AI$64) -> 696 | N21: =SUM('2'!$AF$63:$AF$64) -> 608 | O21: =SUM('3'!$AI$63:$AI$64) -> 657 | P21: =SUM('4'!$AH$63:$AH$64) -> 654 | Q21: =SUM('5'!$AI$63:$AI$64) -> 371 | R21: =SUM('6'!$AH$63:$AH$64) -> 172 | S21: =SUM('7'!$AI$63:$AI$64) -> 0 | T21: =SUM('8'!$AI$63:$AI$64) -> 0 | U21: =SUM('9'!$AH$63:$AH$64) -> 0 | V21: =SUM('10'!$AI$63:$AI$64) -> 0 | W21: =SUM('11'!$AH$63:$AH$64) -> 0 | X21: =SUM('12'!$AI$63:$AI$64) -> 0 | Y21: =SUM(M21:X21) -> 3158
C22: Genéricas | E22: - | F22: - | G22: - | H22: - | J22: 32 | K22: 11635 | L22: =SUM(M22:X22) -> 14165 | M22: ='1'!$AI$65 -> 2437 | N22: ='2'!$AF$65 -> 1789 | O22: ='3'!$AI$65 -> 3053 | P22: ='4'!$AH$65 -> 2786 | Q22: ='5'!$AI$65 -> 3087 | R22: ='6'!$AH$65 -> 1013 | S22: ='7'!$AI$65 -> 0 | T22: ='8'!$AI$65 -> 0 | U22: ='9'!$AH$65 -> 0 | V22: ='10'!$AI$65 -> 0 | W22: ='11'!$AH$65 -> 0 | X22: ='12'!$AI$65 -> 0 | Y22: =SUM(M22:X22) -> 14165
C23: Usuários Atendidos (vendidos) | D23: 0 | E23: 24381 | F23: 81112 | G23: 119341 | H23: 120761 | I23: 122984 | J23: 122458 | K23: 105999 | L23: =SUM(M23:X23) -> 43810 | M23: ='1'!$AI$66 -> 7793 | N23: ='2'!$AF$66 -> 6626 | O23: ='3'!$AI$66 -> 8860 | P23: ='4'!$AH$66 -> 8241 | Q23: ='5'!$AI$66 -> 8498 | R23: ='6'!$AH$66 -> 3792 | S23: ='7'!$AI$66 -> 0 | T23: ='8'!$AI$66 -> 0 | U23: ='9'!$AH$66 -> 0 | V23: ='10'!$AI$66 -> 0 | W23: ='11'!AH67 -> 0 | X23: ='12'!$AI$66 -> 0 | Y23: =SUM(M23:X23) -> 43810
C24: Refeições Servidas | D24: 0 | E24: =123930-3774 -> 120156 | F24: 79859 | G24: 119379 | H24: 119126 | I24: 121957 | J24: 121020 | K24: 100065 | L24: =SUM(M24:X24) -> 41092 | M24: ='1'!$AI$67 -> 7600 | N24: ='2'!$AF$67 -> 6376 | O24: ='3'!$AI$67 -> 8422 | P24: ='4'!$AH$67 -> 8041 | Q24: ='5'!$AI$67 -> 7280 | R24: ='6'!$AH$67 -> 3373 | S24: ='7'!$AI$67 -> 0 | T24: ='8'!$AI$67 -> 0 | U24: ='9'!$AH$67 -> 0 | V24: ='10'!$AI$67 -> 0 | W24: ='11'!AH68 -> 0 | X24: ='12'!$AI$67 -> 0 | Y24: =SUM(M24:X24) -> 41092
C25: Refeições Ofertadas | J25: 10500 | K25: 124000 | L25: =SUM(M25:X25) -> 126500 | M25: ='1'!$AI$68 -> 10500 | N25: ='2'!$AF$68 -> 9000 | O25: ='3'!$AI$68 -> 11000 | P25: ='4'!$AH$68 -> 10000 | Q25: ='5'!$AI$68 -> 10000 | R25: ='6'!$AH$68 -> 10500 | S25: ='7'!$AI$68 -> 11500 | T25: ='8'!$AI$68 -> 10500 | U25: ='9'!$AH$68 -> 11000 | V25: ='10'!$AI$68 -> 11000 | W25: ='11'!AH69 -> 10000 | X25: ='12'!$AI$68 -> 11500 | Y25: =SUM(M25:X25) -> 126500
C26: Pessoas com Deficiência | E26: 1468 | F26: 1913 | G26: 2379 | H26: 1632 | I26: 33 | J26: 137 | K26: 673 | L26: =SUM(M26:X26) -> 137 | M26: ='1'!$AI$71 -> 45 | N26: ='2'!$AF$71 -> 46 | O26: ='3'!$AI$71 -> 28 | P26: ='4'!$AH$71 -> 15 | Q26: ='5'!$AI$71 -> 3 | R26: ='6'!$AH$71 -> 0 | S26: ='7'!$AI$71 -> 0 | T26: ='8'!$AI$71 -> 0 | U26: ='9'!$AH$71 -> 0 | V26: ='10'!$AI$71 -> 0 | W26: ='11'!AH72 -> 0 | X26: ='12'!$AI$71 -> 0 | Y26: =SUM(M26:X26) -> 137
B27: UNIDADE | C27: INDICADORES NOVO ISRAEL | D27: ANO 2018 | E27: ANO 2019 | F27: ANO 2020 | G27: ANO 2021 | H27: ANO 2022 | I27: ANO 2023 | J27: ANO 2024 | K27: ANO 2025 | L27: ANO 2026 | M27: JAN | N27: FEV | O27: MAR | P27: ABR | Q27: MAI | R27: JUN | S27: JUL | T27: AGO | U27: SET | V27: OUT | W27: NOV | X27: DEZ | Y27: TOTAL 2026
B28: NOVO ISRAEL | C28: Novos Cadastros | D28: 0 | E28: 1432 | F28: 1175 | G28: 268 | H28: 1641 | I28: 2172 | J28: 567 | K28: 877 | L28: =SUM(M28:X28) -> 473 | M28: ='1'!$AI$73 -> 56 | N28: ='2'!$AF$73 -> 169 | O28: ='3'!$AI$73 -> 187 | P28: ='4'!$AH$73 -> 61 | Q28: ='5'!AI73 -> 0 | R28: ='6'!$AH$73 -> 0 | S28: ='7'!$AI$73 -> 0 | T28: ='8'!$AI$73 -> 0 | U28: ='9'!$AH$73 -> 0 | V28: ='10'!$AI$73 -> 0 | W28: ='11'!$AH$73 -> 0 | X28: ='12'!$AI$73 -> 0 | Y28: =SUM(M28:X28) -> 473
C29: Pessoas em situação de rua | D29: 0 | E29: 0 | F29: 4568 | G29: 36 | H29: 4694 | I29: 6644 | J29: 5543 | K29: 9820 | L29: =SUM(M29:X29) -> 408 | M29: =SUM('1'!$AI$86:$AI$87) -> 74 | N29: =SUM('2'!$AF$86:$AF$87) -> 81 | O29: =SUM('3'!$AI$86:$AI$87) -> 117 | P29: =SUM('4'!$AH$86:$AH$87) -> 68 | Q29: =SUM('5'!$AI$86:$AI$87) -> 31 | R29: =SUM('6'!$AH$86:$AH$87) -> 37 | S29: =SUM('7'!$AI$86:$AI$87) -> 0 | T29: =SUM('8'!$AI$86:$AI$87) -> 0 | U29: =SUM('9'!$AH$86:$AH$87) -> 0 | V29: =SUM('10'!$AI$86:$AI$87) -> 0 | W29: =SUM('11'!$AH$86:$AH$87) -> 0 | X29: =SUM('12'!$AI$86:$AI$87) -> 0 | Y29: =SUM(M29:X29) -> 408
C30: Genéricas | J30: 236 | K30: 12363 | L30: =SUM(M30:X30) -> 14650 | M30: ='1'!$AI$88 -> 2097 | N30: ='2'!$AF$88 -> 1632 | O30: ='3'!$AI$88 -> 2031 | P30: ='4'!$AH$88 -> 3193 | Q30: ='5'!$AI$88 -> 3837 | R30: ='6'!$AH$88 -> 1860 | S30: ='7'!$AI$88 -> 0 | T30: ='8'!$AI$88 -> 0 | U30: ='9'!$AH$88 -> 0 | V30: ='10'!$AI$88 -> 0 | W30: ='11'!$AH$88 -> 0 | X30: ='12'!$AI$88 -> 0 | Y30: =SUM(M30:X30) -> 14650
C31: Usuários Atendidos (vendidos) | D31: 0 | E31: 21164 | F31: 76353 | G31: 108725 | H31: 110150 | I31: 109595 | J31: 105840 | K31: 106712 | L31: =SUM(M31:X31) -> 45105 | M31: ='1'!$AI$89 -> 8624 | N31: ='2'!$AF$89 -> 7268 | O31: ='3'!$AI$89 -> 8811 | P31: ='4'!$AH$89 -> 7966 | Q31: ='5'!$AI$89 -> 8337 | R31: ='6'!$AH$89 -> 4099 | S31: ='7'!$AI$89 -> 0 | T31: ='8'!$AI$89 -> 0 | U31: ='9'!$AH$89 -> 0 | V31: ='10'!$AI$89 -> 0 | W31: ='11'!$AH$89 -> 0 | X31: ='12'!$AI$89 -> 0 | Y31: =SUM(M31:X31) -> 45105
C32: Refeições Servidas | D32: 0 | E32: =124680-3774 -> 120906 | F32: 77929 | G32: 108060 | H32: 107469 | I32: 113267 | J32: 104858 | K32: 103621 | L32: =SUM(M32:X32) -> 43613 | M32: ='1'!$AI$90 -> 8384 | N32: ='2'!$AF$90 -> 7060 | O32: ='3'!$AI$90 -> 8514 | P32: ='4'!$AH$90 -> 7671 | Q32: ='5'!$AI$90 -> 8020 | R32: ='6'!$AH$90 -> 3964 | S32: ='7'!$AI$90 -> 0 | T32: ='8'!$AI$90 -> 0 | U32: ='9'!$AH$90 -> 0 | V32: ='10'!$AI$90 -> 0 | W32: ='11'!$AH$90 -> 0 | X32: ='12'!$AI$90 -> 0 | Y32: =SUM(M32:X32) -> 43613
C33: Refeições Ofertadas | J33: 9295 | K33: 114200 | L33: =SUM(M33:X33) -> 113850 | M33: ='1'!$AI$91 -> 9450 | N33: ='2'!$AF$91 -> 8100 | O33: ='3'!$AI$91 -> 9900 | P33: ='4'!$AH$91 -> 9000 | Q33: ='5'!$AI$91 -> 9000 | R33: ='6'!$AH$91 -> 9450 | S33: ='7'!$AI$91 -> 10350 | T33: ='8'!$AI$91 -> 9450 | U33: ='9'!$AH$91 -> 9900 | V33: ='10'!$AI$91 -> 9900 | W33: ='11'!$AH$92 -> 9000 | X33: ='12'!$AI$91 -> 10350 | Y33: =SUM(M33:X33) -> 113850
C34: Pessoas com Deficiência | E34: 2832 | F34: 2957 | G34: 2733 | H34: 1522 | I34: 3976 | J34: 1777 | K34: 2675 | L34: =SUM(M34:X34) -> 988 | M34: ='1'!$AI$94 -> 195 | N34: ='2'!$AF$94 -> 456 | O34: ='3'!$AI$94 -> 184 | P34: ='4'!$AH$94 -> 153 | Q34: ='5'!$AI$94 -> 0 | R34: ='6'!$AH$94 -> 0 | S34: ='7'!$AI$94 -> 0 | T34: ='8'!$AI$94 -> 0 | U34: ='9'!$AH$94 -> 0 | V34: ='10'!$AI$94 -> 0 | W34: ='11'!$AH$95 -> 0 | X34: ='12'!$AI$94 -> 0 | Y34: =SUM(M34:X34) -> 988
B35: UNIDADE | C35: INDICADORES ALVORADA | D35: ANO 2018 | E35: ANO 2019 | F35: ANO 2020 | G35: ANO 2021 | H35: ANO 2022 | I35: ANO 2023 | J35: ANO 2024 | K35: ANO 2025 | L35: ANO 2026 | M35: JAN | N35: FEV | O35: MAR | P35: ABR | Q35: MAI | R35: JUN | S35: JUL | T35: AGO | U35: SET | V35: OUT | W35: NOV | X35: DEZ | Y35: TOTAL 2026
B36: ALVORADA Inaugurado 31/03/2022 | C36: Novos Cadastros | D36: 0 | E36: 0 | F36: 0 | G36: 0 | H36: 172 | I36: 1485 | J36: 251 | K36: 280 | L36: =SUM(M36:X36) -> 359 | M36: ='1'!$AI$96 -> 210 | N36: ='2'!$AF$96 -> 69 | O36: ='3'!$AI$96 -> 56 | P36: ='4'!$AH$96 -> 24 | Q36: ='5'!AI96 -> 0 | R36: ='6'!$AH$96 -> 0 | S36: ='7'!$AI$96 -> 0 | T36: ='8'!$AI$96 -> 0 | U36: ='9'!$AH$96 -> 0 | V36: ='10'!$AI$96 -> 0 | W36: ='11'!$AH$96 -> 0 | X36: ='12'!$AI$96 -> 0 | Y36: =SUM(M36:X36) -> 359
C37: Pessoas em situação de rua | D37: 0 | E37: 0 | F37: 0 | G37: 0 | H37: 854 | I37: 3219 | J37: 33 | K37: 1135 | L37: =SUM(M37:X37) -> 1879 | M37: =SUM('1'!$AI$109:$AI$110) -> 336 | N37: =SUM('2'!$AF$109:$AF$110) -> 388 | O37: =SUM('3'!$AI$109:$AI$110) -> 410 | P37: =SUM('4'!$AH$109:$AH$110) -> 242 | Q37: =SUM('5'!$AI$109:$AI$110) -> 298 | R37: =SUM('6'!$AH$109:$AH$110) -> 205 | S37: =SUM('7'!$AI$109:$AI$110) -> 0 | T37: =SUM('8'!$AI$109:$AI$110) -> 0 | U37: =SUM('9'!$AH$109:$AH$110) -> 0 | V37: =SUM('10'!$AI$109:$AI$110) -> 0 | W37: =SUM('11'!$AH$109:$AH$110) -> 0 | X37: =SUM('12'!$AI$109:$AI$110) -> 0 | Y37: =SUM(M37:X37) -> 1879
C38: Genéricas | E38: - | F38: - | G38: - | H38: - | J38: 116 | K38: 2541 | L38: =SUM(M38:X38) -> 1334 | M38: ='1'!$AI$111 -> 414 | N38: ='2'!$AF$111 -> 313 | O38: ='3'!$AI$111 -> 297 | P38: ='4'!$AH$111 -> 210 | Q38: ='5'!$AI$111 -> 83 | R38: ='6'!$AH$111 -> 17 | S38: ='7'!$AI$111 -> 0 | T38: ='8'!$AI$111 -> 0 | U38: ='9'!$AH$111 -> 0 | V38: ='10'!$AI$111 -> 0 | W38: ='11'!$AH$111 -> 0 | X38: ='12'!$AI$111 -> 0 | Y38: =SUM(M38:X38) -> 1334
C39: Usuários Atendidos (vendidos) | D39: 0 | E39: 0 | F39: 0 | G39: 0 | H39: 72385 | I39: 94071 | J39: 89152 | K39: 91092 | L39: =SUM(M39:X39) -> 37020 | M39: ='1'!$AI$112 -> 7033 | N39: ='2'!$AF$112 -> 5975 | O39: ='3'!$AI$112 -> 7559 | P39: ='4'!$AH$112 -> 6450 | Q39: ='5'!$AI$112 -> 6687 | R39: ='6'!$AH$112 -> 3316 | S39: ='7'!$AI$112 -> 0 | T39: ='8'!$AI$112 -> 0 | U39: ='9'!$AH$112 -> 0 | V39: ='10'!$AI$112 -> 0 | W39: ='11'!$AH$112 -> 0 | X39: ='12'!$AI$112 -> 0 | Y39: =SUM(M39:X39) -> 37020
C40: Refeições Servidas | D40: 0 | E40: 0 | F40: 0 | G40: 0 | H40: 69616 | I40: 89962 | J40: 86041 | K40: 90753 | L40: =SUM(M40:X40) -> 36947 | M40: ='1'!$AI$113 -> 7004 | N40: ='2'!$AF$113 -> 5947 | O40: ='3'!$AI$113 -> 7548 | P40: ='4'!$AH$113 -> 6446 | Q40: ='5'!$AI$113 -> 6686 | R40: ='6'!$AH$113 -> 3316 | S40: ='7'!$AI$113 -> 0 | T40: ='8'!$AI$113 -> 0 | U40: ='9'!$AH$113 -> 0 | V40: ='10'!$AI$113 -> 0 | W40: ='11'!$AH$113 -> 0 | X40: ='12'!$AI$113 -> 0 | Y40: =SUM(M40:X40) -> 36947
C41: Refeições Ofertadas | J41: 8000 | K41: 99200 | L41: =SUM(M41:X41) -> 101200 | M41: ='1'!$AI$114 -> 8400 | N41: ='2'!$AF$114 -> 7200 | O41: ='3'!$AI$114 -> 8800 | P41: ='4'!$AH$114 -> 8000 | Q41: ='5'!$AI$114 -> 8000 | R41: ='6'!$AH$114 -> 8400 | S41: ='7'!$AI$114 -> 9200 | T41: ='8'!$AI$114 -> 8400 | U41: ='9'!$AH$114 -> 8800 | V41: ='10'!$AI$114 -> 8800 | W41: ='11'!AH115 -> 8000 | X41: ='12'!$AI$114 -> 9200 | Y41: =SUM(M41:X41) -> 101200
...

Sheet 1
A1: ANO CALENDÁRIO | B1: MÊS | C1: Data | K1: Prato Cheio Capital
A2: 2026 | B2: JANEIRO | C2: =DATE(A2,MATCH(B2,{"JANEIRO";"FEVEREIRO";"MARÇO";"ABRIL";"MAIO";"JUNHO";"JULHO";"AGOSTO";"SETEMBRO";"OUTUBRO";"NOVEMBRO";"DEZEMBRO"},0),1) -> 46023 | D2: =IF(ISERROR(DATE($A$2,$B$3,COLUMN()-3)),"",DAY(DATE($A$2,$B$3,COLUMN()-3))) -> 1 | E2: =IF(ISERROR(DATE($A$2,$B$3,COLUMN()-3)),"",DAY(DATE($A$2,$B$3,COLUMN()-3))) -> 2 | F2: =IF(ISERROR(DATE($A$2,$B$3,COLUMN()-3)),"",DAY(DATE($A$2,$B$3,COLUMN()-3))) -> 3 | G2: =IF(ISERROR(DATE($A$2,$B$3,COLUMN()-3)),"",DAY(DATE($A$2,$B$3,COLUMN()-3))) -> 4 | H2: =IF(ISERROR(DATE($A$2,$B$3,COLUMN()-3)),"",DAY(DATE($A$2,$B$3,COLUMN()-3))) -> 5 | I2: =IF(ISERROR(DATE($A$2,$B$3,COLUMN()-3)),"",DAY(DATE($A$2,$B$3,COLUMN()-3))) -> 6 | J2: =IF(ISERROR(DATE($A$2,$B$3,COLUMN()-3)),"",DAY(DATE($A$2,$B$3,COLUMN()-3))) -> 7 | K2: =IF(ISERROR(DATE($A$2,$B$3,COLUMN()-3)),"",DAY(DATE($A$2,$B$3,COLUMN()-3))) -> 8 | ... AH2: =IF(ISERROR(DATE($A$2,$B$3,COLUMN()-3)),"",DAY(DATE($A$2,$B$3,COLUMN()-3))) -> 31
B3: =MATCH(B2,{"JANEIRO";"FEVEREIRO";"MARÇO";"ABRIL";"MAIO";"JUNHO";"JULHO";"AGOSTO";"SETEMBRO";"OUTUBRO";"NOVEMBRO";"DEZEMBRO"},0) -> 1 | D3: =IF(D2="","",TEXT(DATE($A$2,$B$3,D2),"ddd")) -> qui | E3: =IF(E2="","",TEXT(DATE($A$2,$B$3,E2),"ddd")) -> sex | F3: =IF(F2="","",TEXT(DATE($A$2,$B$3,F2),"ddd")) -> sáb | G3: =IF(G2="","",TEXT(DATE($A$2,$B$3,G2),"ddd")) -> dom | H3: =IF(H2="","",TEXT(DATE($A$2,$B$3,H2),"ddd")) -> seg | I3: =IF(I2="","",TEXT(DATE($A$2,$B$3,I2),"ddd")) -> ter | J3: =IF(J2="","",TEXT(DATE($A$2,$B$3,J2),"ddd")) -> qua | K3: =IF(K2="","",TEXT(DATE($A$2,$B$3,K2),"ddd")) -> qui | ... AH3: =IF(AH2="","",TEXT(DATE($A$2,$B$3,AH2),"ddd")) -> sáb | AJ3: observações:
A4: Restaurante CENTRO | B4: Novos cadastros | E4: 4 | H4: 4 | I4: 1 | J4: 1 | K4: 4 | L4: 0 | O4: 1 | P4: 3 | Q4: 0 | R4: 3 | S4: 6 | V4: 0 | W4: 8 | X4: 1 | Y4: 9 | Z4: 8 | AC4: 2 | AD4: 4 | AE4: 2 | AF4: 1 | AG4: 4 | AI4: =SUM(D4:AH4) -> 66
B5: Usuários por faixa etária | C5: 3-17 anos M | E5: 5 | H5: 5 | I5: 5 | J5: 1 | K5: 7 | L5: 18 | O5: 0 | P5: 2 | Q5: 8 | R5: 11 | S5: 4 | V5: 6 | W5: 1 | X5: 6 | Y5: 6 | Z5: 4 | AC5: 6 | AD5: 5 | AE5: 4 | AF5: 4 | AG5: 7 | AI5: =SUM(D5:AH5) -> 115
C6: 3-17 anos M (PCD) | E6: 0 | H6: 0 | I6: 0 | J6: 0 | K6: 0 | L6: 0 | O6: 0 | P6: 0 | Q6: 0 | R6: 0 | S6: 0 | V6: 0 | W6: 0 | X6: 0 | Y6: 0 | Z6: 0 | AC6: 0 | AD6: 0 | AE6: 0 | AF6: 0 | AG6: 0 | AI6: =SUM(D6:AH6) -> 0
C7: 03-17 anos F | E7: 1 | H7: 1 | I7: 1 | J7: 3 | K7: 2 | L7: 8 | O7: 0 | P7: 2 | Q7: 9 | R7: 6 | S7: 1 | V7: 5 | W7: 1 | X7: 7 | Y7: 3 | Z7: 3 | AC7: 6 | AD7: 4 | AE7: 3 | AF7: 3 | AG7: 5 | AI7: =SUM(D7:AH7) -> 74
C8: 03-17 anos F (PCD) | E8: 0 | H8: 0 | I8: 0 | J8: 0 | K8: 0 | L8: 0 | O8: 0 | P8: 0 | Q8: 0 | R8: 0 | S8: 0 | V8: 0 | W8: 0 | X8: 0 | Y8: 0 | Z8: 0 | AC8: 0 | AD8: 0 | AE8: 0 | AF8: 0 | AG8: 0 | AI8: =SUM(D8:AH8) -> 0
C9: 17-59 M | E9: 114 | H9: 114 | I9: 134 | J9: 124 | K9: 125 | L9: 149 | O9: 103 | P9: 116 | Q9: 134 | R9: 149 | S9: 130 | V9: 96 | W9: 119 | X9: 122 | Y9: 120 | Z9: 103 | AC9: 147 | AD9: 104 | AE9: 107 | AF9: 109 | AG9: 110 | AI9: =SUM(D9:AH9) -> 2529
C10: 17-59 M (PCD) | E10: 1 | H10: 1 | I10: 2 | J10: 2 | K10: 4 | L10: 3 | O10: 1 | P10: 0 | Q10: 1 | R10: 4 | S10: 2 | V10: 1 | W10: 1 | X10: 2 | Y10: 0 | Z10: 0 | AC10: 2 | AD10: 1 | AE10: 3 | AF10: 3 | AG10: 0 | AI10: =SUM(D10:AH10) -> 34
C11: 17-59 F | E11: 11 | H11: 11 | I11: 14 | J11: 14 | K11: 16 | L11: 32 | O11: 12 | P11: 12 | Q11: 30 | R11: 37 | S11: 18 | V11: 9 | W11: 10 | X11: 19 | Y11: 14 | Z11: 15 | AC11: 14 | AD11: 13 | AE11: 13 | AF11: 9 | AG11: 13 | AI11: =SUM(D11:AH11) -> 336
C12: 17-59 F (PCD) | E12: 0 | H12: 0 | I12: 0 | J12: 0 | K12: 1 | L12: 0 | O12: 1 | P12: 0 | Q12: 0 | R12: 0 | S12: 0 | V12: 0 | W12: 0 | X12: 1 | Y12: 0 | Z12: 0 | AC12: 1 | AD12: 0 | AE12: 0 | AF12: 0 | AG12: 0 | AI12: =SUM(D12:AH12) -> 4
C13: a partir de 60 anos M | E13: 148 | H13: 148 | I13: 148 | J13: 133 | K13: 143 | L13: 162 | O13: 118 | P13: 114 | Q13: 136 | R13: 146 | S13: 140 | V13: 127 | W13: 111 | X13: 141 | Y13: 150 | Z13: 121 | AC13: 134 | AD13: 115 | AE13: 131 | AF13: 123 | AG13: 144 | AI13: =SUM(D13:AH13) -> 2833
C14: a partir de 60 anos M (PCD) | E14: 4 | H14: 4 | I14: 3 | J14: 3 | K14: 6 | L14: 4 | O14: 4 | P14: 4 | Q14: 6 | R14: 6 | S14: 4 | V14: 5 | W14: 4 | X14: 3 | Y14: 5 | Z14: 4 | AC14: 5 | AD14: 7 | AE14: 3 | AF14: 5 | AG14: 6 | AI14: =SUM(D14:AH14) -> 95
C15: a partir de 60 anos F | E15: 7 | H15: 7 | I15: 10 | J15: 11 | K15: 7 | L15: 22 | O15: 8 | P15: 11 | Q15: 12 | R15: 20 | S15: 14 | V15: 5 | W15: 10 | X15: 6 | Y15: 10 | Z15: 6 | AC15: 7 | AD15: 8 | AE15: 6 | AF15: 9 | AG15: 6 | AI15: =SUM(D15:AH15) -> 202
C16: a partir de 60 anos F (PCD) | E16: 0 | H16: 0 | I16: 0 | J16: 0 | K16: 0 | L16: 0 | O16: 0 | P16: 0 | Q16: 0 | R16: 1 | S16: 0 | V16: 0 | W16: 0 | X16: 0 | Y16: 1 | Z16: 0 | AC16: 0 | AD16: 1 | AE16: 1 | AF16: 1 | AG16: 0 | AI16: =SUM(D16:AH16) -> 5
C17: Pessoas em situação de rua M | E17: 160 | H17: 160 | I17: 84 | J17: 156 | K17: 90 | L17: 134 | O17: 79 | P17: 84 | Q17: 137 | R17: 134 | S17: 104 | V17: 91 | W17: 93 | X17: 147 | Y17: 84 | Z17: 72 | AC17: 147 | AD17: 85 | AE17: 69 | AF17: 86 | AG17: 148 | AI17: =SUM(D17:AH17) -> 2344
... C19: sem cadastro (genéricas) | E19: 141 | H19: 141 | I19: 195 | J19: 140 | K19: 190 | L19: 60 | O19: 272 | P19: 248 | Q19: 119 | R19: 72 | S19: 182 | V19: 247 | W19: 242 | X19: 112 | Y19: 206 | Z19: 269 | AC19: 122 | AD19: 253 | AE19: 255 | AF19: 240 | AG19: 151 | AI19: =SUM(D19:AH19) -> 3857
B20: Usuários ATENDIDOS (ref. Vendidas) | E20: =SUM(E5:E19) -> 600 | H20: =SUM(H5:H19) -> 600 | I20: =SUM(I5:I19) -> 600 | J20: =SUM(J5:J19) -> 600 | K20: =SUM(K5:K19) -> 595 | L20: =SUM(L5:L19) -> 600 | O20: =SUM(O5:O19) -> 600 | P20: =SUM(P5:P19) -> 600 | Q20: =SUM(Q5:Q19) -> 600 | R20: =SUM(R5:R19) -> 600 | S20: =SUM(S5:S19) -> 600 | V20: =SUM(V5:V19) -> 600 | W20: =SUM(W5:W19) -> 600 | X20: =SUM(X5:X19) -> 582 | Y20: =SUM(Y5:Y19) -> 600 | Z20: =SUM(Z5:Z19) -> 600 | AC20: =SUM(AC5:AC19) -> 600 | AD20: =SUM(AD5:AD19) -> 600 | AE20: =SUM(AE5:AE19) -> 600 | AF20: =SUM(AF5:AF19) -> 600 | AG20: =SUM(AG5:AG19) -> 600 | AI20: =SUM(D20:AH20) -> 12577
B21: Refeições Servidas | E21: 598 | H21: 598 | I21: 584 | J21: 579 | K21: 577 | L21: 580 | O21: 580 | P21: 585 | Q21: 581 | R21: 592 | S21: 600 | V21: 569 | W21: 587 | X21: 578 | Y21: 587 | Z21: 586 | AC21: 592 | AD21: 595 | AE21: 576 | AF21: 595 | AG21: 600 | AI21: =SUM(D21:AH21) -> 12319
B22: REFEIÇÕES OFERTADAS | E22: 600 | H22: 600 | I22: 600 | J22: 600 | K22: 600 | L22: 600 | O22: 600 | P22: 600 | Q22: 600 | R22: 600 | S22: 600 | V22: 600 | W22: 600 | X22: 600 | Y22: 600 | Z22: 600 | AC22: 600 | AD22: 600 | AE22: 600 | AF22: 600 | AG22: 600 | AI22: =SUM(D22:AH22) -> 12600
B23: SOBRA DE REFEIÇÕES | E23: =E22-E21 -> 2 | H23: =H22-H21 -> 2 | I23: =I22-I21 -> 16 | J23: =J22-J21 -> 21 | K23: =K22-K21 -> 23 | L23: =L22-L21 -> 20 | O23: =O22-O21 -> 20 | P23: =P22-P21 -> 15 | Q23: =Q22-Q21 -> 19 | R23: =R22-R21 -> 8 | S23: =S22-S21 -> 0 | V23: =V22-V21 -> 31 | W23: =W22-W21 -> 13 | X23: =X22-X21 -> 22 | Y23: =Y22-Y21 -> 13 | Z23: =Z22-Z21 -> 14 | AC23: =AC22-AC21 -> 8 | AD23: =AD22-AD21 -> 5 | AE23: =AE22-AE21 -> 24 | AF23: =AF22-AF21 -> 5 | AG23: =AG22-AG21 -> 0 | AI23: =SUM(D23:AH23) -> 281
B24: SOBRA DE SENHAS (não vendidas) | E24: =E22-E20 -> 0 | H24: =H22-H20 -> 0 | I24: =I22-I20 -> 0 | J24: =J22-J20 -> 0 | K24: =K22-K20 -> 5 | L24: =L22-L20 -> 0 | O24: =O22-O20 -> 0 | P24: =P22-P20 -> 0 | Q24: =Q22-Q20 -> 0 | R24: =R22-R20 -> 0 | S24: =S22-S20 -> 0 | V24: =V22-V20 -> 0 | W24: =W22-W20 -> 0 | X24: =X22-X20 -> 18 | Y24: =Y22-Y20 -> 0 | Z24: =Z22-Z20 -> 0 | AC24: =AC22-AC20 -> 0 | AD24: =AD22-AD20 -> 0 | AE24: =AE22-AE20 -> 0 | AF24: =AF22-AF20 -> 0 | AG24: =AG22-AG20 -> 0 | AI24: =SUM(D24:AH24) -> 23
B25: Atendimento à Pessoas com Deficiência | E25: =E6+E8+E10+E12+E14+E16 -> 5 | H25: =H6+H8+H10+H12+H14+H16 -> 5 | I25: =I6+I8+I10+I12+I14+I16 -> 5 | J25: =J6+J8+J10+J12+J14+J16 -> 5 | K25: =K6+K8+K10+K12+K14+K16 -> 11 | L25: =L6+L8+L10+L12+L14+L16 -> 7 | O25: =O6+O8+O10+O12+O14+O16 -> 6 | P25: =P6+P8+P10+P12+P14+P16 -> 4 | Q25: =Q6+Q8+Q10+Q12+Q14+Q16 -> 7 | R25: =R6+R8+R10+R12+R14+R16 -> 11 | S25: =S6+S8+S10+S12+S14+S16 -> 6 | V25: =V6+V8+V10+V12+V14+V16 -> 6 | W25: =W6+W8+W10+W12+W14+W16 -> 5 | X25: =X6+X8+X10+X12+X14+X16 -> 6 | Y25: =Y6+Y8+Y10+Y12+Y14+Y16 -> 6 | Z25: =Z6+Z8+Z10+Z12+Z14+Z16 -> 4 | AC25: =AC6+AC8+AC10+AC12+AC14+AC16 -> 8 | AD25: =AD6+AD8+AD10+AD12+AD14+AD16 -> 9 | AE25: =AE6+AE8+AE10+AE12+AE14+AE16 -> 7 | AF25: =SUM(AF6,AF8,AF10,AF12,AF14,AF16) -> 9 | AG25: =SUM(AG6,AG8,AG10,AG12,AG14,AG16) -> 6 | AI25: =SUM(D25:AH25) -> 138
AJ26: observações:
A27: Restaurante COMPENSA | B27: Novos cadastros | E27: 0 | H27: 0 | I27: 0 | J27: 0 | K27: 0 | L27: 0 | O27: 0 | P27: 0 | Q27: 0 | R27: 0 | S27: 0 | V27: 0 | W27: 0 | X27: 0 | Y27: 0 | Z27: 0 | AC27: 0 | AD27: 0 | AE27: 0 | AF27: 0 | AG27: 0 | AI27: =SUM(D27:AH27) -> 0 | AJ27: computador da unidade está queimado
B28: Usuários por faixa etária | C28: 3-17 anos M | E28: 0 | H28: 0 | I28: 0 | J28: 0 | K28: 0 | L28: 0 | O28: 0 | P28: 0 | Q28: 0 | R28: 0 | S28: 0 | V28: 0 | W28: 0 | X28: 0 | Y28: 0 | Z28: 0 | AC28: 0 | AD28: 0 | AE28: 0 | AF28: 0 | AG28: 0 | AI28: =SUM(D28:AH28) -> 0
C29: 3-17 anos M (PCD) | E29: 0 | H29: 0 | I29: 0 | J29: 0 | K29: 0 | L29: 0 | O29: 0 | P29: 0 | Q29: 0 | R29: 0 | S29: 0 | V29: 0 | W29: 0 | X29: 0 | Y29: 0 | Z29: 0 | AC29: 0 | AD29: 0 | AE29: 0 | AF29: 0 | AG29: 0 | AI29: =SUM(D29:AH29) -> 0
C30: 03-17 anos F | E30: 0 | H30: 0 | I30: 0 | J30: 0 | K30: 0 | L30: 0 | O30: 0 | P30: 0 | Q30: 0 | R30: 0 | S30: 0 | V30: 0 | W30: 0 | X30: 0 | Y30: 0 | Z30: 0 | AC30: 0 | AD30: 0 | AE30: 0 | AF30: 0 | AG30: 0 | AI30: =SUM(D30:AH30) -> 0
C31: 03-17 anos F (PCD) | E31: 0 | H31: 0 | I31: 0 | J31: 0 | K31: 0 | L31: 0 | O31: 0 | P31: 0 | Q31: 0 | R31: 0 | S31: 0 | V31: 0 | W31: 0 | X31: 0 | Y31: 0 | Z31: 0 | AC31: 0 | AD31: 0 | AE31: 0 | AF31: 0 | AG31: 0 | AI31: =SUM(D31:AH31) -> 0
C32: 17-59 M | E32: 0 | H32: 0 | I32: 0 | J32: 0 | K32: 0 | L32: 0 | O32: 0 | P32: 0 | Q32: 0 | R32: 0 | S32: 0 | V32: 0 | W32: 0 | X32: 0 | Y32: 0 | Z32: 0 | AC32: 0 | AD32: 0 | AE32: 0 | AF32: 0 | AG32: 0 | AI32: =SUM(D32:AH32) -> 0
C33: 17-59 M (PCD) | E33: 0 | H33: 0 | I33: 0 | J33: 0 | K33: 0 | L33: 0 | O33: 0 | P33: 0 | Q33: 0 | R33: 0 | S33: 0 | V33: 0 | W33: 0 | X33: 0 | Y33: 0 | Z33: 0 | AC33: 0 | AD33: 0 | AE33: 0 | AF33: 0 | AG33: 0 | AI33: =SUM(D33:AH33) -> 0
C34: 17-59 F | E34: 0 | H34: 0 | I34: 0 | J34: 0 | K34: 0 | L34: 0 | O34: 0 | P34: 0 | Q34: 0 | R34: 0 | S34: 0 | V34: 0 | W34: 0 | X34: 0 | Y34: 0 | Z34: 0 | AC34: 0 | AD34: 0 | AE34: 0 | AF34: 0 | AG34: 0 | AI34: =SUM(D34:AH34) -> 0
C35: 17-59 F (PCD) | E35: 0 | H35: 0 | I35: 0 | J35: 0 | K35: 0 | L35: 0 | O35: 0 | P35: 0 | Q35: 0 | R35: 0 | S35: 0 | V35: 0 | W35: 0 | X35: 0 | Y35: 0 | Z35: 0 | AC35: 0 | AD35: 0 | AE35: 0 | AF35: 0 | AG35: 0 | AI35: =SUM(D35:AH35) -> 0
C36: a partir de 60 anos M | E36: 0 | H36: 0 | I36: 0 | J36: 0 | K36: 0 | L36: 0 | O36: 0 | P36: 0 | Q36: 0 | R36: 0 | S36: 0 | V36: 0 | W36: 0 | X36: 0 | Y36: 0 | Z36: 0 | AC36: 0 | AD36: 0 | AE36: 0 | AF36: 0 | AG36: 0 | AI36: =SUM(D36:AH36) -> 0
C37: a partir de 60 anos M (PCD) | E37: 0 | H37: 0 | I37: 0 | J37: 0 | K37: 0 | L37: 0 | O37: 0 | P37: 0 | Q37: 0 | R37: 0 | S37: 0 | V37: 0 | W37: 0 | X37: 0 | Y37: 0 | Z37: 0 | AC37: 0 | AD37: 0 | AE37: 0 | AF37: 0 | AG37: 0 | AI37: =SUM(D37:AH37) -> 0
C38: a partir de 60 anos F | E38: 0 | H38: 0 | I38: 0 | J38: 0 | K38: 0 | L38: 0 | O38: 0 | P38: 0 | Q38: 0 | R38: 0 | S38: 0 | V38: 0 | W38: 0 | X38: 0 | Y38: 0 | Z38: 0 | AC38: 0 | AD38: 0 | AE38: 0 | AF38: 0 | AG38: 0 | AI38: =SUM(D38:AH38) -> 0
C39: a partir de 60 anos F (PCD) | E39: 0 | H39: 0 | I39: 0 | J39: 0 | K39: 0 | L39: 0 | O39: 0 | P39: 0 | Q39: 0 | R39: 0 | S39: 0 | V39: 0 | W39: 0 | X39: 0 | Y39: 0 | Z39: 0 | AC39: 0 | AD39: 0 | AE39: 0 | AF39: 0 | AG39: 0 | AI39: =SUM(D39:AH39) -> 0
C40: Pessoas em situação de rua M | E40: 0 | H40: 0 | I40: 0 | J40: 0 | K40: 0 | L40: 0 | O40: 0 | P40: 0 | Q40: 0 | R40: 0 | S40: 0 | V40: 0 | W40: 0 | X40: 0 | Y40: 0 | Z40: 0 | AC40: 0 | AD40: 0 | AE40: 0 | AF40: 0 | AG40: 0 | AI40: =SUM(D40:AH40) -> 0
... C42: sem cadastro (genéricas) | E42: 0 | H42: 0 | I42: 0 | J42: 0 | K42: 0 | L42: 0 | O42: 0 | P42: 0 | Q42: 0 | R42: 0 | S42: 0 | V42: 0 | W42: 0 | X42: 0 | Y42: 0 | Z42: 0 | AC42: 0 | AD42: 0 | AE42: 0 | AF42: 0 | AG42: 0 | AI42: =SUM(D42:AH42) -> 0
...

Sheet 2
A1: ANO CALENDÁRIO | B1: MÊS | C1: Data | K1: Prato Cheio Capital
A2: 2026 | B2: FEVEREIRO | C2: =DATE(A2,MATCH(B2,{"JANEIRO";"FEVEREIRO";"MARÇO";"ABRIL";"MAIO";"JUNHO";"JULHO";"AGOSTO";"SETEMBRO";"OUTUBRO";"NOVEMBRO";"DEZEMBRO"},0),1) -> 46054 | D2: =IF(ISERROR(DATE($A$2,$B$3,COLUMN()-3)),"",DAY(DATE($A$2,$B$3,COLUMN()-3))) -> 1 | E2: =IF(ISERROR(DATE($A$2,$B$3,COLUMN()-3)),"",DAY(DATE($A$2,$B$3,COLUMN()-3))) -> 2 | F2: =IF(ISERROR(DATE($A$2,$B$3,COLUMN()-3)),"",DAY(DATE($A$2,$B$3,COLUMN()-3))) -> 3 | G2: =IF(ISERROR(DATE($A$2,$B$3,COLUMN()-3)),"",DAY(DATE($A$2,$B$3,COLUMN()-3))) -> 4 | H2: =IF(ISERROR(DATE($A$2,$B$3,COLUMN()-3)),"",DAY(DATE($A$2,$B$3,COLUMN()-3))) -> 5 | I2: =IF(ISERROR(DATE($A$2,$B$3,COLUMN()-3)),"",DAY(DATE($A$2,$B$3,COLUMN()-3))) -> 6 | J2: =IF(ISERROR(DATE($A$2,$B$3,COLUMN()-3)),"",DAY(DATE($A$2,$B$3,COLUMN()-3))) -> 7 | K2: =IF(ISERROR(DATE($A$2,$B$3,COLUMN()-3)),"",DAY(DATE($A$2,$B$3,COLUMN()-3))) -> 8 | ... AE2: =IF(ISERROR(DATE($A$2,$B$3,COLUMN()-3)),"",DAY(DATE($A$2,$B$3,COLUMN()-3))) -> 28
B3: =MATCH(B2,{"JANEIRO";"FEVEREIRO";"MARÇO";"ABRIL";"MAIO";"JUNHO";"JULHO";"AGOSTO";"SETEMBRO";"OUTUBRO";"NOVEMBRO";"DEZEMBRO"},0) -> 2 | D3: =IF(D2="","",TEXT(DATE($A$2,$B$3,D2),"ddd")) -> dom | E3: =IF(E2="","",TEXT(DATE($A$2,$B$3,E2),"ddd")) -> seg | F3: =IF(F2="","",TEXT(DATE($A$2,$B$3,F2),"ddd")) -> ter | G3: =IF(G2="","",TEXT(DATE($A$2,$B$3,G2),"ddd")) -> qua | H3: =IF(H2="","",TEXT(DATE($A$2,$B$3,H2),"ddd")) -> qui | I3: =IF(I2="","",TEXT(DATE($A$2,$B$3,I2),"ddd")) -> sex | J3: =IF(J2="","",TEXT(DATE($A$2,$B$3,J2),"ddd")) -> sáb | K3: =IF(K2="","",TEXT(DATE($A$2,$B$3,K2),"ddd")) -> dom | ... AE3: =IF(AE2="","",TEXT(DATE($A$2,$B$3,AE2),"ddd")) -> sáb | AG3: observações:
A4: Restaurante CENTRO | B4: Novos cadastros | E4: 3 | F4: 2 | G4: 16 | H4: 0 | I4: 0 | L4: 5 | M4: 0 | N4: 0 | O4: 0 | P4: 3 | S4: 3 | V4: 5 | W4: 0 | Z4: 1 | AA4: 2 | AB4: 11 | AC4: 2 | AD4: 4 | AF4: =SUM(D4:AE4) -> 57
B5: Usuários por faixa etária | C5: 3-17 anos M | E5: 6 | F5: 2 | G5: 5 | H5: 2 | I5: 4 | L5: 9 | M5: 16 | N5: 5 | O5: 10 | P5: 3 | S5: 1 | V5: 8 | W5: 5 | Z5: 2 | AA5: 5 | AB5: 9 | AC5: 2 | AD5: 4 | AF5: =SUM(D5:AE5) -> 98
C6: 3-17 anos M (PCD) | E6: 0 | F6: 0 | G6: 0 | H6: 0 | I6: 0 | L6: 0 | M6: 0 | N6: 0 | O6: 0 | P6: 0 | S6: 0 | V6: 0 | W6: 0 | Z6: 0 | AA6: 0 | AB6: 0 | AC6: 0 | AD6: 0 | AF6: =SUM(D6:AE6) -> 0
C7: 03-17 anos F | E7: 0 | F7: 1 | G7: 1 | H7: 1 | I7: 0 | L7: 7 | M7: 16 | N7: 2 | O7: 6 | P7: 4 | S7: 0 | V7: 6 | W7: 2 | Z7: 0 | AA7: 2 | AB7: 0 | AC7: 2 | AD7: 4 | AF7: =SUM(D7:AE7) -> 54
C8: 03-17 anos F (PCD) | E8: 0 | F8: 0 | G8: 0 | H8: 0 | I8: 0 | L8: 0 | M8: 0 | N8: 0 | O8: 0 | P8: 0 | S8: 0 | V8: 0 | W8: 0 | Z8: 0 | AA8: 0 | AB8: 0 | AC8: 0 | AD8: 0 | AF8: =SUM(D8:AE8) -> 0
C9: 17-59 M | E9: 132 | F9: 125 | G9: 107 | H9: 121 | I9: 98 | L9: 111 | M9: 127 | N9: 108 | O9: 111 | P9: 108 | S9: 100 | V9: 121 | W9: 144 | Z9: 122 | AA9: 117 | AB9: 124 | AC9: 100 | AD9: 118 | AF9: =SUM(D9:AE9) -> 2094
C10: 17-59 M (PCD) | E10: 2 | F10: 3 | G10: 4 | H10: 0 | I10: 3 | L10: 1 | M10: 1 | N10: 0 | O10: 2 | P10: 2 | S10: 2 | V10: 1 | W10: 3 | Z10: 1 | AA10: 3 | AB10: 3 | AC10: 0 | AD10: 1 | AF10: =SUM(D10:AE10) -> 32
C11: 17-59 F | E11: 10 | F11: 9 | G11: 10 | H11: 11 | I11: 14 | L11: 21 | M11: 30 | N11: 15 | O11: 17 | P11: 11 | S11: 9 | V11: 18 | W11: 14 | Z11: 11 | AA11: 18 | AB11: 9 | AC11: 13 | AD11: 9 | AF11: =SUM(D11:AE11) -> 249
C12: 17-59 F (PCD) | E12: 0 | F12: 0 | G12: 0 | H12: 0 | I12: 0 | L12: 0 | M12: 1 | N12: 0 | O12: 0 | P12: 0 | S12: 0 | V12: 0 | W12: 0 | Z12: 0 | AA12: 0 | AB12: 0 | AC12: 0 | AD12: 0 | AF12: =SUM(D12:AE12) -> 1
C13: a partir de 60 anos M | E13: 125 | F13: 106 | G13: 119 | H13: 140 | I13: 111 | L13: 110 | M13: 141 | N13: 118 | O13: 133 | P13: 132 | S13: 100 | V13: 135 | W13: 148 | Z13: 106 | AA13: 134 | AB13: 133 | AC13: 108 | AD13: 124 | AF13: =SUM(D13:AE13) -> 2223
C14: a partir de 60 anos M (PCD) | E14: 5 | F14: 5 | G14: 4 | H14: 4 | I14: 4 | L14: 7 | M14: 6 | N14: 4 | O14: 9 | P14: 3 | S14: 5 | V14: 7 | W14: 6 | Z14: 7 | AA14: 8 | AB14: 8 | AC14: 7 | AD14: 7 | AF14: =SUM(D14:AE14) -> 106
C15: a partir de 60 anos F | E15: 9 | F15: 9 | G15: 7 | H15: 11 | I15: 9 | L15: 9 | M15: 16 | N15: 8 | O15: 6 | P15: 7 | S15: 7 | V15: 7 | W15: 8 | Z15: 11 | AA15: 8 | AB15: 10 | AC15: 4 | AD15: 5 | AF15: =SUM(D15:AE15) -> 151
C16: a partir de 60 anos F (PCD) | E16: 1 | F16: 1 | G16: 0 | H16: 0 | I16: 0 | L16: 0 | M16: 1 | N16: 1 | O16: 0 | P16: 1 | S16: 0 | V16: 0 | W16: 1 | Z16: 1 | AA16: 0 | AB16: 0 | AC16: 0 | AD16: 1 | AF16: =SUM(D16:AE16) -> 8
C17: Pessoas em situação de rua M | E17: 101 | F17: 71 | G17: 69 | H17: 95 | I17: 54 | L17: 114 | M17: 133 | N17: 66 | O17: 95 | P17: 68 | S17: 55 | V17: 106 | W17: 81 | Z17: 86 | AA17: 67 | AB17: 100 | AC17: 150 | AD17: 78 | AF17: =SUM(D17:AE17) -> 1589
... C19: sem cadastro (genéricas) | E19: 174 | F19: 266 | G19: 269 | H19: 211 | I19: 300 | L19: 206 | M19: 103 | N19: 268 | O19: 207 | P19: 257 | S19: 167 | V19: 181 | W19: 185 | Z19: 248 | AA19: 236 | AB19: 192 | AC19: 101 | AD19: 249 | AF19: =SUM(D19:AE19) -> 3820
B20: Usuários ATENDIDOS (ref. Vendidas) | E20: =SUM(E5:E19) -> 568 | F20: =SUM(F5:F19) -> 600 | G20: =SUM(G5:G19) -> 600 | H20: =SUM(H5:H19) -> 600 | I20: =SUM(I5:I19) -> 600 | L20: =SUM(L5:L19) -> 600 | M20: =SUM(M5:M19) -> 600 | N20: =SUM(N5:N19) -> 600 | O20: =SUM(O5:O19) -> 600 | P20: =SUM(P5:P19) -> 600 | S20: =SUM(S5:S19) -> 457 | V20: =SUM(V5:V19) -> 600 | W20: =SUM(W5:W19) -> 600 | Z20: =SUM(Z5:Z19) -> 600 | AA20: =SUM(AA5:AA19) -> 600 | AB20: =SUM(AB5:AB19) -> 595 | AC20: =SUM(AC5:AC19) -> 492 | AD20: =SUM(AD5:AD19) -> 600 | AF20: =SUM(D20:AE20) -> 10512
B21: Refeições Servidas | E21: 555 | F21: 582 | G21: 590 | H21: 583 | I21: 600 | L21: 597 | M21: 582 | N21: 600 | O21: 578 | P21: 590 | S21: 452 | V21: 584 | W21: 586 | Z21: 593 | AA21: 581 | AB21: 595 | AC21: 487 | AD21: 585 | AF21: =SUM(D21:AE21) -> 10320
B22: REFEIÇÕES OFERTADAS | E22: 600 | F22: 600 | G22: 600 | H22: 600 | I22: 600 | L22: 600 | M22: 600 | N22: 600 | O22: 600 | P22: 600 | S22: 600 | V22: 600 | W22: 600 | Z22: 600 | AA22: 600 | AB22: 600 | AC22: 600 | AD22: 600 | AF22: =SUM(D22:AE22) -> 10800
B23: SOBRA DE REFEIÇÕES | E23: =E22-E21 -> 45 | F23: =F22-F21 -> 18 | G23: =G22-G21 -> 10 | H23: =H22-H21 -> 17 | I23: =I22-I21 -> 0 | L23: =L22-L21 -> 3 | M23: =M22-M21 -> 18 | N23: =N22-N21 -> 0 | O23: =O22-O21 -> 22 | P23: =P22-P21 -> 10 | S23: =S22-S21 -> 148 | V23: =V22-V21 -> 16 | W23: =W22-W21 -> 14 | Z23: =Z22-Z21 -> 7 | AA23: =AA22-AA21 -> 19 | AB23: =AB22-AB21 -> 5 | AC23: =AC22-AC21 -> 113 | AD23: =AD22-AD21 -> 15 | AF23: =SUM(D23:AE23) -> 480
B24: SOBRA DE SENHAS (não vendidas) | E24: =E22-E20 -> 32 | F24: =F22-F20 -> 0 | G24: =G22-G20 -> 0 | H24: =H22-H20 -> 0 | I24: =I22-I20 -> 0 | L24: =L22-L20 -> 0 | M24: =M22-M20 -> 0 | N24: =N22-N20 -> 0 | O24: =O22-O20 -> 0 | P24: =P22-P20 -> 0 | S24: =S22-S20 -> 143 | V24: =V22-V20 -> 0 | W24: =W22-W20 -> 0 | Z24: =Z22-Z20 -> 0 | AA24: =AA22-AA20 -> 0 | AB24: =AB22-AB20 -> 5 | AC24: =AC22-AC20 -> 108 | AD24: =AD22-AD20 -> 0 | AF24: =SUM(D24:AE24) -> 288
B25: Atendimento à Pessoas com Deficiência | E25: =E6+E8+E10+E12+E14+E16 -> 8 | F25: =F6+F8+F10+F12+F14+F16 -> 9 | G25: =G6+G8+G10+G12+G14+G16 -> 8 | H25: =H6+H8+H10+H12+H14+H16 -> 4 | I25: =I6+I8+I10+I12+I14+I16 -> 7 | L25: =L6+L8+L10+L12+L14+L16 -> 8 | M25: =M6+M8+M10+M12+M14+M16 -> 9 | N25: =N7+N9+N11+N13+N15+N17 -> 317 | O25: =O6+O8+O10+O12+O14+O16 -> 11 | P25: =P6+P8+P10+P12+P14+P16 -> 6 | S25: =S6+S8+S10+S12+S14+S16 -> 7 | V25: =V6+V8+V10+V12+V14+V16 -> 8 | W25: =W6+W8+W10+W12+W14+W16 -> 10 | Z25: =Z6+Z8+Z10+Z12+Z14+Z16 -> 9 | AA25: =AA6+AA8+AA10+AA12+AA14+AA16 -> 11 | AB25: =AB6+AB8+AB10+AB12+AB14+AB16 -> 11 | AC25: =AC6+AC8+AC10+AC12+AC14+AC16 -> 7 | AD25: =AD6+AD8+AD10+AD12+AD14+AD16 -> 9 | AF25: =SUM(D25:AE25) -> 459
AG26: observações:
A27: Restaurante COMPENSA | B27: Novos cadastros | E27: 0 | F27: 0 | G27: 0 | H27: 0 | I27: 0 | L27: 0 | M27: 0 | N27: 0 | O27: 0 | P27: 0 | S27: 0 | V27: 5 | W27: 6 | Z27: 0 | AA27: 0 | AB27: 0 | AC27: 0 | AD27: 0 | AF27: =SUM(D27:AE27) -> 11
B28: Usuários por faixa etária | C28: 3-17 anos M | E28: 0 | F28: 0 | G28: 0 | H28: 0 | I28: 0 | L28: 0 | M28: 0 | N28: 0 | O28: 0 | P28: 0 | S28: 0 | V28: 3 | W28: 2 | Z28: 0 | AA28: 0 | AB28: 0 | AC28: 0 | AD28: 0 | AF28: =SUM(D28:AE28) -> 5
C29: 3-17 anos M (PCD) | E29: 0 | F29: 0 | G29: 0 | H29: 0 | I29: 0 | L29: 0 | M29: 0 | N29: 0 | O29: 0 | P29: 0 | S29: 0 | V29: 1 | W29: 1 | Z29: 0 | AA29: 0 | AB29: 0 | AC29: 0 | AD29: 0 | AF29: =SUM(D29:AE29) -> 2
C30: 03-17 anos F | E30: 0 | F30: 0 | G30: 0 | H30: 0 | I30: 0 | L30: 0 | M30: 0 | N30: 0 | O30: 0 | P30: 0 | S30: 0 | V30: 5 | W30: 6 | Z30: 0 | AA30: 0 | AB30: 0 | AC30: 0 | AD30: 0 | AF30: =SUM(D30:AE30) -> 11
C31: 03-17 anos F (PCD) | E31: 0 | F31: 0 | G31: 0 | H31: 0 | I31: 0 | L31: 0 | M31: 0 | N31: 0 | O31: 0 | P31: 0 | S31: 0 | V31: 0 | W31: 0 | Z31: 0 | AA31: 0 | AB31: 0 | AC31: 0 | AD31: 0 | AF31: =SUM(D31:AE31) -> 0
C32: 17-59 M | E32: 0 | F32: 0 | G32: 0 | H32: 0 | I32: 0 | L32: 0 | M32: 0 | N32: 0 | O32: 0 | P32: 0 | S32: 0 | V32: 89 | W32: 79 | Z32: 0 | AA32: 0 | AB32: 0 | AC32: 0 | AD32: 0 | AF32: =SUM(D32:AE32) -> 168
C33: 17-59 M (PCD) | E33: 0 | F33: 0 | G33: 0 | H33: 0 | I33: 0 | L33: 0 | M33: 0 | N33: 0 | O33: 0 | P33: 0 | S33: 0 | V33: 4 | W33: 4 | Z33: 0 | AA33: 0 | AB33: 0 | AC33: 0 | AD33: 0 | AF33: =SUM(D33:AE33) -> 8
C34: 17-59 F | E34: 0 | F34: 0 | G34: 0 | H34: 0 | I34: 0 | L34: 0 | M34: 0 | N34: 0 | O34: 0 | P34: 0 | S34: 0 | V34: 31 | W34: 32 | Z34: 0 | AA34: 0 | AB34: 0 | AC34: 0 | AD34: 0 | AF34: =SUM(D34:AE34) -> 63
C35: 17-59 F (PCD) | E35: 0 | F35: 0 | G35: 0 | H35: 0 | I35: 0 | L35: 0 | M35: 0 | N35: 0 | O35: 0 | P35: 0 | S35: 0 | V35: 2 | W35: 3 | Z35: 0 | AA35: 0 | AB35: 0 | AC35: 0 | AD35: 0 | AF35: =SUM(D35:AE35) -> 5
C36: a partir de 60 anos M | E36: 0 | F36: 0 | G36: 0 | H36: 0 | I36: 0 | L36: 0 | M36: 0 | N36: 0 | O36: 0 | P36: 0 | S36: 0 | V36: 80 | W36: 71 | Z36: 0 | AA36: 0 | AB36: 0 | AC36: 0 | AD36: 0 | AF36: =SUM(D36:AE36) -> 151
C37: a partir de 60 anos M (PCD) | E37: 0 | F37: 0 | G37: 0 | H37: 0 | I37: 0 | L37: 0 | M37: 0 | N37: 0 | O37: 0 | P37: 0 | S37: 0 | V37: 4 | W37: 5 | Z37: 0 | AA37: 0 | AB37: 0 | AC37: 0 | AD37: 0 | AF37: =SUM(D37:AE37) -> 9
C38: a partir de 60 anos F | E38: 0 | F38: 0 | G38: 0 | H38: 0 | I38: 0 | L38: 0 | M38: 0 | N38: 0 | O38: 0 | P38: 0 | S38: 0 | V38: 21 | W38: 23 | Z38: 0 | AA38: 0 | AB38: 0 | AC38: 0 | AD38: 0 | AF38: =SUM(D38:AE38) -> 44
C39: a partir de 60 anos F (PCD) | E39: 0 | F39: 0 | G39: 0 | H39: 0 | I39: 0 | L39: 0 | M39: 0 | N39: 0 | O39: 0 | P39: 0 | S39: 0 | V39: 2 | W39: 2 | Z39: 0 | AA39: 0 | AB39: 0 | AC39: 0 | AD39: 0 | AF39: =SUM(D39:AE39) -> 4
C40: Pessoas em situação de rua M | E40: 0 | F40: 0 | G40: 0 | H40: 0 | I40: 0 | L40: 0 | M40: 0 | N40: 0 | O40: 0 | P40: 0 | S40: 0 | V40: 20 | W40: 14 | Z40: 0 | AA40: 0 | AB40: 0 | AC40: 0 | AD40: 0 | AF40: =SUM(D40:AE40) -> 34
... C42: sem cadastro (genéricas) | E42: 0 | F42: 0 | G42: 0 | H42: 0 | I42: 0 | L42: 0 | M42: 0 | N42: 0 | O42: 0 | P42: 0 | S42: 0 | V42: 8 | W42: 27 | Z42: 0 | AA42: 0 | AB42: 0 | AC42: 0 | AD42: 0 | AF42: =SUM(D42:AE42) -> 35
...

Sheet 3
A1: ANO CALENDÁRIO | B1: MÊS | C1: Data | K1: Prato Cheio Capital
A2: 2026 | B2: MARÇO | C2: =DATE(A2,MATCH(B2,{"JANEIRO";"FEVEREIRO";"MARÇO";"ABRIL";"MAIO";"JUNHO";"JULHO";"AGOSTO";"SETEMBRO";"OUTUBRO";"NOVEMBRO";"DEZEMBRO"},0),1) -> 46082 | D2: =IF(ISERROR(DATE($A$2,$B$3,COLUMN()-3)),"",DAY(DATE($A$2,$B$3,COLUMN()-3))) -> 1 | E2: =IF(ISERROR(DATE($A$2,$B$3,COLUMN()-3)),"",DAY(DATE($A$2,$B$3,COLUMN()-3))) -> 2 | F2: =IF(ISERROR(DATE($A$2,$B$3,COLUMN()-3)),"",DAY(DATE($A$2,$B$3,COLUMN()-3))) -> 3 | G2: =IF(ISERROR(DATE($A$2,$B$3,COLUMN()-3)),"",DAY(DATE($A$2,$B$3,COLUMN()-3))) -> 4 | H2: =IF(ISERROR(DATE($A$2,$B$3,COLUMN()-3)),"",DAY(DATE($A$2,$B$3,COLUMN()-3))) -> 5 | I2: =IF(ISERROR(DATE($A$2,$B$3,COLUMN()-3)),"",DAY(DATE($A$2,$B$3,COLUMN()-3))) -> 6 | J2: =IF(ISERROR(DATE($A$2,$B$3,COLUMN()-3)),"",DAY(DATE($A$2,$B$3,COLUMN()-3))) -> 7 | K2: =IF(ISERROR(DATE($A$2,$B$3,COLUMN()-3)),"",DAY(DATE($A$2,$B$3,COLUMN()-3))) -> 8 | ... AH2: =IF(ISERROR(DATE($A$2,$B$3,COLUMN()-3)),"",DAY(DATE($A$2,$B$3,COLUMN()-3))) -> 31
B3: =MATCH(B2,{"JANEIRO";"FEVEREIRO";"MARÇO";"ABRIL";"MAIO";"JUNHO";"JULHO";"AGOSTO";"SETEMBRO";"OUTUBRO";"NOVEMBRO";"DEZEMBRO"},0) -> 3 | D3: =IF(D2="","",TEXT(DATE($A$2,$B$3,D2),"ddd")) -> dom | E3: =IF(E2="","",TEXT(DATE($A$2,$B$3,E2),"ddd")) -> seg | F3: =IF(F2="","",TEXT(DATE($A$2,$B$3,F2),"ddd")) -> ter | G3: =IF(G2="","",TEXT(DATE($A$2,$B$3,G2),"ddd")) -> qua | H3: =IF(H2="","",TEXT(DATE($A$2,$B$3,H2),"ddd")) -> qui | I3: =IF(I2="","",TEXT(DATE($A$2,$B$3,I2),"ddd")) -> sex | J3: =IF(J2="","",TEXT(DATE($A$2,$B$3,J2),"ddd")) -> sáb | K3: =IF(K2="","",TEXT(DATE($A$2,$B$3,K2),"ddd")) -> dom | ... AH3: =IF(AH2="","",TEXT(DATE($A$2,$B$3,AH2),"ddd")) -> ter | AJ3: observações:
A4: Restaurante CENTRO | B4: Novos cadastros | E4: 0 | F4: 6 | G4: 21 | H4: 5 | I4: 3 | L4: 12 | M4: 0 | N4: 1 | O4: 26 | P4: 5 | S4: 4 | T4: 2 | U4: 6 | V4: 11 | W4: 20 | Z4: 6 | AA4: 3 | AB4: 9 | AC4: 0 | AD4: 1 | AG4: 9 | AH4: 10 | AI4: =SUM(D4:AH4) -> 160
B5: Usuários por faixa etária | C5: 3-17 anos M | E5: 6 | F5: 4 | G5: 11 | H5: 5 | I5: 7 | L5: 4 | M5: 4 | N5: 3 | O5: 12 | P5: 3 | S5: 9 | T5: 5 | U5: 4 | V5: 0 | W5: 7 | Z5: 2 | AA5: 9 | AB5: 5 | AC5: 11 | AD5: 4 | AG5: 6 | AH5: 5 | AI5: =SUM(D5:AH5) -> 126
C6: 3-17 anos M (PCD) | E6: 0 | F6: 0 | G6: 0 | H6: 0 | I6: 0 | L6: 0 | M6: 0 | N6: 0 | O6: 0 | P6: 0 | S6: 0 | T6: 0 | U6: 0 | V6: 0 | W6: 0 | Z6: 0 | AA6: 0 | AB6: 0 | AC6: 0 | AD6: 0 | AG6: 0 | AH6: 0 | AI6: =SUM(D6:AH6) -> 0
C7: 03-17 anos F | E7: 1 | F7: 3 | G7: 10 | H7: 0 | I7: 8 | L7: 3 | M7: 6 | N7: 1 | O7: 3 | P7: 1 | S7: 6 | T7: 3 | U7: 4 | V7: 3 | W7: 2 | Z7: 2 | AA7: 2 | AB7: 1 | AC7: 1 | AD7: 1 | AG7: 3 | AH7: 2 | AI7: =SUM(D7:AH7) -> 66
C8: 03-17 anos F (PCD) | E8: 0 | F8: 0 | G8: 0 | H8: 0 | I8: 0 | L8: 0 | M8: 0 | N8: 0 | O8: 0 | P8: 0 | S8: 0 | T8: 0 | U8: 0 | V8: 0 | W8: 0 | Z8: 0 | AA8: 0 | AB8: 0 | AC8: 0 | AD8: 0 | AG8: 0 | AH8: 0 | AI8: =SUM(D8:AH8) -> 0
C9: 17-59 M | E9: 130 | F9: 146 | G9: 121 | H9: 111 | I9: 100 | L9: 138 | M9: 100 | N9: 119 | O9: 126 | P9: 153 | S9: 117 | T9: 118 | U9: 86 | V9: 138 | W9: 117 | Z9: 118 | AA9: 136 | AB9: 142 | AC9: 130 | AD9: 108 | AG9: 123 | AH9: 152 | AI9: =SUM(D9:AH9) -> 2729
C10: 17-59 M (PCD) | E10: 4 | F10: 1 | G10: 0 | H10: 4 | I10: 1 | L10: 2 | M10: 1 | N10: 1 | O10: 1 | P10: 4 | S10: 4 | T10: 2 | U10: 0 | V10: 3 | W10: 1 | Z10: 2 | AA10: 1 | AB10: 5 | AC10: 2 | AD10: 1 | AG10: 1 | AH10: 2 | AI10: =SUM(D10:AH10) -> 43
C11: 17-59 F | E11: 12 | F11: 18 | G11: 22 | H11: 10 | I11: 22 | L11: 35 | M11: 18 | N11: 13 | O11: 10 | P11: 22 | S11: 28 | T11: 19 | U11: 10 | V11: 17 | W11: 17 | Z11: 13 | AA11: 12 | AB11: 15 | AC11: 17 | AD11: 15 | AG11: 9 | AH11: 18 | AI11: =SUM(D11:AH11) -> 372
C12: 17-59 F (PCD) | E12: 0 | F12: 0 | G12: 0 | H12: 0 | I12: 0 | L12: 2 | M12: 0 | N12: 0 | O12: 0 | P12: 0 | S12: 0 | T12: 0 | U12: 0 | V12: 1 | W12: 1 | Z12: 0 | AA12: 0 | AB12: 0 | AC12: 0 | AD12: 0 | AG12: 1 | AH12: 0 | AI12: =SUM(D12:AH12) -> 5
C13: a partir de 60 anos M | E13: 135 | F13: 128 | G13: 128 | H13: 116 | I13: 135 | L13: 152 | M13: 126 | N13: 120 | O13: 123 | P13: 142 | S13: 131 | T13: 114 | U13: 88 | V13: 129 | W13: 122 | Z13: 117 | AA13: 130 | AB13: 142 | AC13: 116 | AD13: 114 | AG13: 115 | AH13: 155 | AI13: =SUM(D13:AH13) -> 2778
C14: a partir de 60 anos M (PCD) | E14: 6 | F14: 6 | G14: 6 | H14: 4 | I14: 6 | L14: 6 | M14: 5 | N14: 4 | O14: 7 | P14: 6 | S14: 7 | T14: 8 | U14: 8 | V14: 6 | W14: 5 | Z14: 8 | AA14: 8 | AB14: 9 | AC14: 10 | AD14: 5 | AG14: 5 | AH14: 5 | AI14: =SUM(D14:AH14) -> 140
C15: a partir de 60 anos F | E15: 11 | F15: 12 | G15: 8 | H15: 7 | I15: 13 | L15: 31 | M15: 15 | N15: 6 | O15: 10 | P15: 14 | S15: 10 | T15: 6 | U15: 6 | V15: 12 | W15: 6 | Z15: 5 | AA15: 7 | AB15: 12 | AC15: 10 | AD15: 5 | AG15: 10 | AH15: 5 | AI15: =SUM(D15:AH15) -> 221
